[2019-12-03 18:07:56,222] [WARNING] [processlist_view] : 朱占豪测试日志级别
[2019-12-03 18:19:15,589] [WARNING] [get_response] : Not Found: /accounts/login/
[2019-12-03 18:19:15,590] [WARNING] [log_message] : "GET /accounts/login/?next=/web_index/ HTTP/1.1" 404 11267
[2019-12-03 18:19:15,679] [WARNING] [get_response] : Not Found: /favicon.ico
[2019-12-03 18:19:15,680] [WARNING] [log_message] : "GET /favicon.ico HTTP/1.1" 404 11238
[2019-12-03 18:21:46,099] [WARNING] [processlist_view] : 朱占豪测试日志级别
[2019-12-03 18:21:48,882] [WARNING] [processlist_view] : 朱占豪测试日志级别
[2019-12-03 19:48:31,758] [WARNING] [processlist_view] : 朱占豪测试日志级别
[2019-12-03 19:48:47,067] [WARNING] [processlist_view] : 朱占豪测试日志级别
[2019-12-03 19:52:34,023] [WARNING] [processlist_view] : 朱占豪测试日志级别
[2019-12-03 19:52:36,204] [WARNING] [processlist_view] : 朱占豪测试日志级别
[2019-12-03 19:52:43,403] [WARNING] [processlist_view] : 朱占豪测试日志级别
[2019-12-03 23:20:57,067] [WARNING] [processlist_view] : 朱占豪测试日志级别
[2019-12-04 11:15:42,462] [ERROR] [handle_uncaught_exception] : Internal Server Error: /processlist/
Traceback (most recent call last):
  File "/Library/Frameworks/Python.framework/Versions/3.6/lib/python3.6/site-packages/django/core/handlers/exception.py", line 41, in inner
    response = get_response(request)
  File "/Library/Frameworks/Python.framework/Versions/3.6/lib/python3.6/site-packages/django/core/handlers/base.py", line 187, in _get_response
    response = self.process_exception_by_middleware(e, request)
  File "/Library/Frameworks/Python.framework/Versions/3.6/lib/python3.6/site-packages/django/core/handlers/base.py", line 185, in _get_response
    response = wrapped_callback(request, *callback_args, **callback_kwargs)
  File "/Library/Frameworks/Python.framework/Versions/3.6/lib/python3.6/site-packages/django/contrib/auth/decorators.py", line 23, in _wrapped_view
    return view_func(request, *args, **kwargs)
  File "/Users/zhuzhanhao/Testapi/Api/view_process.py", line 291, in processlist_view
    for weblist in apilists:
UnboundLocalError: local variable 'apilists' referenced before assignment
[2019-12-04 11:15:42,808] [ERROR] [log_message] : "GET /processlist/?page=1&limit=30&belong=&system=erms&filterSos=%5B%7B%22prefix%22%3A%22and%22%2C%22field%22%3A%22casename%22%2C%22mode%22%3A%22condition%22%2C%22type%22%3A%22eq%22%2C%22value%22%3A%22%E6%96%B0%E5%BB%BA%22%2C%22id%22%3A1%7D%5D HTTP/1.1" 500 15560
[2019-12-04 11:34:52,436] [ERROR] [handle_uncaught_exception] : Internal Server Error: /processlist/
Traceback (most recent call last):
  File "/Library/Frameworks/Python.framework/Versions/3.6/lib/python3.6/site-packages/django/core/handlers/exception.py", line 41, in inner
    response = get_response(request)
  File "/Library/Frameworks/Python.framework/Versions/3.6/lib/python3.6/site-packages/django/core/handlers/base.py", line 187, in _get_response
    response = self.process_exception_by_middleware(e, request)
  File "/Library/Frameworks/Python.framework/Versions/3.6/lib/python3.6/site-packages/django/core/handlers/base.py", line 185, in _get_response
    response = wrapped_callback(request, *callback_args, **callback_kwargs)
  File "/Library/Frameworks/Python.framework/Versions/3.6/lib/python3.6/site-packages/django/contrib/auth/decorators.py", line 23, in _wrapped_view
    return view_func(request, *args, **kwargs)
  File "/Users/zhuzhanhao/Testapi/Api/view_process.py", line 117, in processlist_view
    for i in json.loads(filterSos):
  File "/Library/Frameworks/Python.framework/Versions/3.6/lib/python3.6/json/__init__.py", line 354, in loads
    return _default_decoder.decode(s)
  File "/Library/Frameworks/Python.framework/Versions/3.6/lib/python3.6/json/decoder.py", line 339, in decode
    obj, end = self.raw_decode(s, idx=_w(s, 0).end())
  File "/Library/Frameworks/Python.framework/Versions/3.6/lib/python3.6/json/decoder.py", line 357, in raw_decode
    raise JSONDecodeError("Expecting value", s, err.value) from None
json.decoder.JSONDecodeError: Expecting value: line 1 column 1 (char 0)
[2019-12-04 11:34:52,569] [ERROR] [log_message] : "GET /processlist/?page=1&limit=30&belong=&system=erms&key%5Bcasename%5D=%E9%94%99%E8%AF%AF%E6%8E%A5%E5%8F%A3%E6%9F%A5%E8%AF%A2 HTTP/1.1" 500 15984
[2019-12-04 11:36:23,666] [ERROR] [handle_uncaught_exception] : Internal Server Error: /processlist/
Traceback (most recent call last):
  File "/Library/Frameworks/Python.framework/Versions/3.6/lib/python3.6/site-packages/django/core/handlers/exception.py", line 41, in inner
    response = get_response(request)
  File "/Library/Frameworks/Python.framework/Versions/3.6/lib/python3.6/site-packages/django/core/handlers/base.py", line 187, in _get_response
    response = self.process_exception_by_middleware(e, request)
  File "/Library/Frameworks/Python.framework/Versions/3.6/lib/python3.6/site-packages/django/core/handlers/base.py", line 185, in _get_response
    response = wrapped_callback(request, *callback_args, **callback_kwargs)
  File "/Library/Frameworks/Python.framework/Versions/3.6/lib/python3.6/site-packages/django/contrib/auth/decorators.py", line 23, in _wrapped_view
    return view_func(request, *args, **kwargs)
  File "/Users/zhuzhanhao/Testapi/Api/view_process.py", line 117, in processlist_view
    for i in json.loads(filterSos):
  File "/Library/Frameworks/Python.framework/Versions/3.6/lib/python3.6/json/__init__.py", line 354, in loads
    return _default_decoder.decode(s)
  File "/Library/Frameworks/Python.framework/Versions/3.6/lib/python3.6/json/decoder.py", line 339, in decode
    obj, end = self.raw_decode(s, idx=_w(s, 0).end())
  File "/Library/Frameworks/Python.framework/Versions/3.6/lib/python3.6/json/decoder.py", line 357, in raw_decode
    raise JSONDecodeError("Expecting value", s, err.value) from None
json.decoder.JSONDecodeError: Expecting value: line 1 column 1 (char 0)
[2019-12-04 11:36:23,690] [ERROR] [log_message] : "GET /processlist/?page=1&limit=30&belong=&system=erms&key%5Bcasename%5D=%E9%94%99%E8%AF%AF%E6%8E%A5%E5%8F%A3%E6%9F%A5%E8%AF%A2 HTTP/1.1" 500 15984
[2019-12-04 11:36:56,429] [ERROR] [handle_uncaught_exception] : Internal Server Error: /processlist/
Traceback (most recent call last):
  File "/Library/Frameworks/Python.framework/Versions/3.6/lib/python3.6/site-packages/django/core/handlers/exception.py", line 41, in inner
    response = get_response(request)
  File "/Library/Frameworks/Python.framework/Versions/3.6/lib/python3.6/site-packages/django/core/handlers/base.py", line 187, in _get_response
    response = self.process_exception_by_middleware(e, request)
  File "/Library/Frameworks/Python.framework/Versions/3.6/lib/python3.6/site-packages/django/core/handlers/base.py", line 185, in _get_response
    response = wrapped_callback(request, *callback_args, **callback_kwargs)
  File "/Library/Frameworks/Python.framework/Versions/3.6/lib/python3.6/site-packages/django/contrib/auth/decorators.py", line 23, in _wrapped_view
    return view_func(request, *args, **kwargs)
  File "/Users/zhuzhanhao/Testapi/Api/view_process.py", line 117, in processlist_view
    for i in json.loads(filterSos):
  File "/Library/Frameworks/Python.framework/Versions/3.6/lib/python3.6/json/__init__.py", line 354, in loads
    return _default_decoder.decode(s)
  File "/Library/Frameworks/Python.framework/Versions/3.6/lib/python3.6/json/decoder.py", line 339, in decode
    obj, end = self.raw_decode(s, idx=_w(s, 0).end())
  File "/Library/Frameworks/Python.framework/Versions/3.6/lib/python3.6/json/decoder.py", line 357, in raw_decode
    raise JSONDecodeError("Expecting value", s, err.value) from None
json.decoder.JSONDecodeError: Expecting value: line 1 column 1 (char 0)
[2019-12-04 11:36:56,457] [ERROR] [log_message] : "GET /processlist/?page=1&limit=30&belong=&system=erms&key%5Bcasename%5D=A HTTP/1.1" 500 15861
[2019-12-04 11:38:32,017] [ERROR] [handle_uncaught_exception] : Internal Server Error: /processlist/
Traceback (most recent call last):
  File "/Library/Frameworks/Python.framework/Versions/3.6/lib/python3.6/site-packages/django/core/handlers/exception.py", line 41, in inner
    response = get_response(request)
  File "/Library/Frameworks/Python.framework/Versions/3.6/lib/python3.6/site-packages/django/core/handlers/base.py", line 187, in _get_response
    response = self.process_exception_by_middleware(e, request)
  File "/Library/Frameworks/Python.framework/Versions/3.6/lib/python3.6/site-packages/django/core/handlers/base.py", line 185, in _get_response
    response = wrapped_callback(request, *callback_args, **callback_kwargs)
  File "/Library/Frameworks/Python.framework/Versions/3.6/lib/python3.6/site-packages/django/contrib/auth/decorators.py", line 23, in _wrapped_view
    return view_func(request, *args, **kwargs)
  File "/Users/zhuzhanhao/Testapi/Api/view_process.py", line 117, in processlist_view
    for i in json.loads(filterSos):
  File "/Library/Frameworks/Python.framework/Versions/3.6/lib/python3.6/json/__init__.py", line 354, in loads
    return _default_decoder.decode(s)
  File "/Library/Frameworks/Python.framework/Versions/3.6/lib/python3.6/json/decoder.py", line 339, in decode
    obj, end = self.raw_decode(s, idx=_w(s, 0).end())
  File "/Library/Frameworks/Python.framework/Versions/3.6/lib/python3.6/json/decoder.py", line 357, in raw_decode
    raise JSONDecodeError("Expecting value", s, err.value) from None
json.decoder.JSONDecodeError: Expecting value: line 1 column 1 (char 0)
[2019-12-04 11:38:32,160] [ERROR] [log_message] : "GET /processlist/?page=1&limit=30&belong=&system=erms&key%5Bcasename%5D=%E9%94%99%E8%AF%AF%E6%8E%A5%E5%8F%A3%E6%9F%A5%E8%AF%A2 HTTP/1.1" 500 15984
[2019-12-06 22:34:34,349] [ERROR] [handle_uncaught_exception] : Internal Server Error: /web_index/
Traceback (most recent call last):
  File "/Library/Frameworks/Python.framework/Versions/3.6/lib/python3.6/site-packages/django/core/handlers/exception.py", line 41, in inner
    response = get_response(request)
  File "/Library/Frameworks/Python.framework/Versions/3.6/lib/python3.6/site-packages/django/core/handlers/base.py", line 187, in _get_response
    response = self.process_exception_by_middleware(e, request)
  File "/Library/Frameworks/Python.framework/Versions/3.6/lib/python3.6/site-packages/django/core/handlers/base.py", line 185, in _get_response
    response = wrapped_callback(request, *callback_args, **callback_kwargs)
  File "/Library/Frameworks/Python.framework/Versions/3.6/lib/python3.6/site-packages/django/contrib/auth/decorators.py", line 23, in _wrapped_view
    return view_func(request, *args, **kwargs)
  File "/Users/zhuzhanhao/Testapi/Api/views.py", line 69, in web_index_views
    return render(request, 'static/index.html')
  File "/Library/Frameworks/Python.framework/Versions/3.6/lib/python3.6/site-packages/django/shortcuts.py", line 30, in render
    content = loader.render_to_string(template_name, context, request, using=using)
  File "/Library/Frameworks/Python.framework/Versions/3.6/lib/python3.6/site-packages/django/template/loader.py", line 67, in render_to_string
    template = get_template(template_name, using=using)
  File "/Library/Frameworks/Python.framework/Versions/3.6/lib/python3.6/site-packages/django/template/loader.py", line 25, in get_template
    raise TemplateDoesNotExist(template_name, chain=chain)
django.template.exceptions.TemplateDoesNotExist: static/index.html
[2019-12-06 22:34:34,534] [ERROR] [log_message] : "GET /web_index/ HTTP/1.1" 500 83578
[2019-12-06 22:34:35,385] [WARNING] [get_response] : Not Found: /favicon.ico
[2019-12-06 22:34:35,386] [WARNING] [log_message] : "GET /favicon.ico HTTP/1.1" 404 11238
[2019-12-06 22:36:19,127] [ERROR] [handle_uncaught_exception] : Internal Server Error: /web_index/
Traceback (most recent call last):
  File "/Library/Frameworks/Python.framework/Versions/3.6/lib/python3.6/site-packages/django/core/handlers/exception.py", line 41, in inner
    response = get_response(request)
  File "/Library/Frameworks/Python.framework/Versions/3.6/lib/python3.6/site-packages/django/core/handlers/base.py", line 187, in _get_response
    response = self.process_exception_by_middleware(e, request)
  File "/Library/Frameworks/Python.framework/Versions/3.6/lib/python3.6/site-packages/django/core/handlers/base.py", line 185, in _get_response
    response = wrapped_callback(request, *callback_args, **callback_kwargs)
  File "/Library/Frameworks/Python.framework/Versions/3.6/lib/python3.6/site-packages/django/contrib/auth/decorators.py", line 23, in _wrapped_view
    return view_func(request, *args, **kwargs)
  File "/Users/zhuzhanhao/Testapi/Api/views.py", line 69, in web_index_views
    return render(request, 'static/index.html')
  File "/Library/Frameworks/Python.framework/Versions/3.6/lib/python3.6/site-packages/django/shortcuts.py", line 30, in render
    content = loader.render_to_string(template_name, context, request, using=using)
  File "/Library/Frameworks/Python.framework/Versions/3.6/lib/python3.6/site-packages/django/template/loader.py", line 67, in render_to_string
    template = get_template(template_name, using=using)
  File "/Library/Frameworks/Python.framework/Versions/3.6/lib/python3.6/site-packages/django/template/loader.py", line 25, in get_template
    raise TemplateDoesNotExist(template_name, chain=chain)
django.template.exceptions.TemplateDoesNotExist: static/index.html
[2019-12-06 22:36:19,198] [ERROR] [log_message] : "GET /web_index/ HTTP/1.1" 500 83578
[2019-12-06 22:36:22,257] [ERROR] [handle_uncaught_exception] : Internal Server Error: /web_index/
Traceback (most recent call last):
  File "/Library/Frameworks/Python.framework/Versions/3.6/lib/python3.6/site-packages/django/core/handlers/exception.py", line 41, in inner
    response = get_response(request)
  File "/Library/Frameworks/Python.framework/Versions/3.6/lib/python3.6/site-packages/django/core/handlers/base.py", line 187, in _get_response
    response = self.process_exception_by_middleware(e, request)
  File "/Library/Frameworks/Python.framework/Versions/3.6/lib/python3.6/site-packages/django/core/handlers/base.py", line 185, in _get_response
    response = wrapped_callback(request, *callback_args, **callback_kwargs)
  File "/Library/Frameworks/Python.framework/Versions/3.6/lib/python3.6/site-packages/django/contrib/auth/decorators.py", line 23, in _wrapped_view
    return view_func(request, *args, **kwargs)
  File "/Users/zhuzhanhao/Testapi/Api/views.py", line 69, in web_index_views
    return render(request, 'static/index.html')
  File "/Library/Frameworks/Python.framework/Versions/3.6/lib/python3.6/site-packages/django/shortcuts.py", line 30, in render
    content = loader.render_to_string(template_name, context, request, using=using)
  File "/Library/Frameworks/Python.framework/Versions/3.6/lib/python3.6/site-packages/django/template/loader.py", line 67, in render_to_string
    template = get_template(template_name, using=using)
  File "/Library/Frameworks/Python.framework/Versions/3.6/lib/python3.6/site-packages/django/template/loader.py", line 25, in get_template
    raise TemplateDoesNotExist(template_name, chain=chain)
django.template.exceptions.TemplateDoesNotExist: static/index.html
[2019-12-06 22:36:22,314] [ERROR] [log_message] : "GET /web_index/ HTTP/1.1" 500 83578
[2019-12-06 22:36:25,717] [ERROR] [handle_uncaught_exception] : Internal Server Error: /web_index/
Traceback (most recent call last):
  File "/Library/Frameworks/Python.framework/Versions/3.6/lib/python3.6/site-packages/django/core/handlers/exception.py", line 41, in inner
    response = get_response(request)
  File "/Library/Frameworks/Python.framework/Versions/3.6/lib/python3.6/site-packages/django/core/handlers/base.py", line 187, in _get_response
    response = self.process_exception_by_middleware(e, request)
  File "/Library/Frameworks/Python.framework/Versions/3.6/lib/python3.6/site-packages/django/core/handlers/base.py", line 185, in _get_response
    response = wrapped_callback(request, *callback_args, **callback_kwargs)
  File "/Library/Frameworks/Python.framework/Versions/3.6/lib/python3.6/site-packages/django/contrib/auth/decorators.py", line 23, in _wrapped_view
    return view_func(request, *args, **kwargs)
  File "/Users/zhuzhanhao/Testapi/Api/views.py", line 69, in web_index_views
    return render(request, 'static/index.html')
  File "/Library/Frameworks/Python.framework/Versions/3.6/lib/python3.6/site-packages/django/shortcuts.py", line 30, in render
    content = loader.render_to_string(template_name, context, request, using=using)
  File "/Library/Frameworks/Python.framework/Versions/3.6/lib/python3.6/site-packages/django/template/loader.py", line 67, in render_to_string
    template = get_template(template_name, using=using)
  File "/Library/Frameworks/Python.framework/Versions/3.6/lib/python3.6/site-packages/django/template/loader.py", line 25, in get_template
    raise TemplateDoesNotExist(template_name, chain=chain)
django.template.exceptions.TemplateDoesNotExist: static/index.html
[2019-12-06 22:36:25,780] [ERROR] [log_message] : "GET /web_index/ HTTP/1.1" 500 83578
[2019-12-06 22:41:15,253] [ERROR] [handle_uncaught_exception] : Internal Server Error: /web_index/
Traceback (most recent call last):
  File "/Library/Frameworks/Python.framework/Versions/3.6/lib/python3.6/site-packages/django/core/handlers/exception.py", line 41, in inner
    response = get_response(request)
  File "/Library/Frameworks/Python.framework/Versions/3.6/lib/python3.6/site-packages/django/core/handlers/base.py", line 187, in _get_response
    response = self.process_exception_by_middleware(e, request)
  File "/Library/Frameworks/Python.framework/Versions/3.6/lib/python3.6/site-packages/django/core/handlers/base.py", line 185, in _get_response
    response = wrapped_callback(request, *callback_args, **callback_kwargs)
  File "/Library/Frameworks/Python.framework/Versions/3.6/lib/python3.6/site-packages/django/contrib/auth/decorators.py", line 23, in _wrapped_view
    return view_func(request, *args, **kwargs)
  File "/Users/zhuzhanhao/Testapi/Api/views.py", line 69, in web_index_views
    return render(request, 'static/index.html')
  File "/Library/Frameworks/Python.framework/Versions/3.6/lib/python3.6/site-packages/django/shortcuts.py", line 30, in render
    content = loader.render_to_string(template_name, context, request, using=using)
  File "/Library/Frameworks/Python.framework/Versions/3.6/lib/python3.6/site-packages/django/template/loader.py", line 67, in render_to_string
    template = get_template(template_name, using=using)
  File "/Library/Frameworks/Python.framework/Versions/3.6/lib/python3.6/site-packages/django/template/loader.py", line 25, in get_template
    raise TemplateDoesNotExist(template_name, chain=chain)
django.template.exceptions.TemplateDoesNotExist: static/index.html
[2019-12-06 22:41:15,416] [ERROR] [log_message] : "GET /web_index/ HTTP/1.1" 500 83578
[2019-12-06 22:41:17,923] [ERROR] [handle_uncaught_exception] : Internal Server Error: /web_index/
Traceback (most recent call last):
  File "/Library/Frameworks/Python.framework/Versions/3.6/lib/python3.6/site-packages/django/core/handlers/exception.py", line 41, in inner
    response = get_response(request)
  File "/Library/Frameworks/Python.framework/Versions/3.6/lib/python3.6/site-packages/django/core/handlers/base.py", line 187, in _get_response
    response = self.process_exception_by_middleware(e, request)
  File "/Library/Frameworks/Python.framework/Versions/3.6/lib/python3.6/site-packages/django/core/handlers/base.py", line 185, in _get_response
    response = wrapped_callback(request, *callback_args, **callback_kwargs)
  File "/Library/Frameworks/Python.framework/Versions/3.6/lib/python3.6/site-packages/django/contrib/auth/decorators.py", line 23, in _wrapped_view
    return view_func(request, *args, **kwargs)
  File "/Users/zhuzhanhao/Testapi/Api/views.py", line 69, in web_index_views
    return render(request, 'static/index.html')
  File "/Library/Frameworks/Python.framework/Versions/3.6/lib/python3.6/site-packages/django/shortcuts.py", line 30, in render
    content = loader.render_to_string(template_name, context, request, using=using)
  File "/Library/Frameworks/Python.framework/Versions/3.6/lib/python3.6/site-packages/django/template/loader.py", line 67, in render_to_string
    template = get_template(template_name, using=using)
  File "/Library/Frameworks/Python.framework/Versions/3.6/lib/python3.6/site-packages/django/template/loader.py", line 25, in get_template
    raise TemplateDoesNotExist(template_name, chain=chain)
django.template.exceptions.TemplateDoesNotExist: static/index.html
[2019-12-06 22:41:17,978] [ERROR] [log_message] : "GET /web_index/ HTTP/1.1" 500 83578
[2019-12-06 22:50:46,861] [ERROR] [handle_uncaught_exception] : Internal Server Error: /web_index/
Traceback (most recent call last):
  File "/Library/Frameworks/Python.framework/Versions/3.6/lib/python3.6/site-packages/django/core/handlers/exception.py", line 41, in inner
    response = get_response(request)
  File "/Library/Frameworks/Python.framework/Versions/3.6/lib/python3.6/site-packages/django/core/handlers/base.py", line 187, in _get_response
    response = self.process_exception_by_middleware(e, request)
  File "/Library/Frameworks/Python.framework/Versions/3.6/lib/python3.6/site-packages/django/core/handlers/base.py", line 185, in _get_response
    response = wrapped_callback(request, *callback_args, **callback_kwargs)
  File "/Library/Frameworks/Python.framework/Versions/3.6/lib/python3.6/site-packages/django/contrib/auth/decorators.py", line 23, in _wrapped_view
    return view_func(request, *args, **kwargs)
  File "/Users/zhuzhanhao/Testapi/Api/views.py", line 69, in web_index_views
    return render(request, 'static/index.html')
  File "/Library/Frameworks/Python.framework/Versions/3.6/lib/python3.6/site-packages/django/shortcuts.py", line 30, in render
    content = loader.render_to_string(template_name, context, request, using=using)
  File "/Library/Frameworks/Python.framework/Versions/3.6/lib/python3.6/site-packages/django/template/loader.py", line 67, in render_to_string
    template = get_template(template_name, using=using)
  File "/Library/Frameworks/Python.framework/Versions/3.6/lib/python3.6/site-packages/django/template/loader.py", line 25, in get_template
    raise TemplateDoesNotExist(template_name, chain=chain)
django.template.exceptions.TemplateDoesNotExist: static/index.html
[2019-12-06 22:50:46,934] [ERROR] [log_message] : "GET /web_index/ HTTP/1.1" 500 83578
[2019-12-06 22:50:48,631] [ERROR] [handle_uncaught_exception] : Internal Server Error: /web_index/
Traceback (most recent call last):
  File "/Library/Frameworks/Python.framework/Versions/3.6/lib/python3.6/site-packages/django/core/handlers/exception.py", line 41, in inner
    response = get_response(request)
  File "/Library/Frameworks/Python.framework/Versions/3.6/lib/python3.6/site-packages/django/core/handlers/base.py", line 187, in _get_response
    response = self.process_exception_by_middleware(e, request)
  File "/Library/Frameworks/Python.framework/Versions/3.6/lib/python3.6/site-packages/django/core/handlers/base.py", line 185, in _get_response
    response = wrapped_callback(request, *callback_args, **callback_kwargs)
  File "/Library/Frameworks/Python.framework/Versions/3.6/lib/python3.6/site-packages/django/contrib/auth/decorators.py", line 23, in _wrapped_view
    return view_func(request, *args, **kwargs)
  File "/Users/zhuzhanhao/Testapi/Api/views.py", line 69, in web_index_views
    return render(request, 'static/index.html')
  File "/Library/Frameworks/Python.framework/Versions/3.6/lib/python3.6/site-packages/django/shortcuts.py", line 30, in render
    content = loader.render_to_string(template_name, context, request, using=using)
  File "/Library/Frameworks/Python.framework/Versions/3.6/lib/python3.6/site-packages/django/template/loader.py", line 67, in render_to_string
    template = get_template(template_name, using=using)
  File "/Library/Frameworks/Python.framework/Versions/3.6/lib/python3.6/site-packages/django/template/loader.py", line 25, in get_template
    raise TemplateDoesNotExist(template_name, chain=chain)
django.template.exceptions.TemplateDoesNotExist: static/index.html
[2019-12-06 22:50:48,692] [ERROR] [log_message] : "GET /web_index/ HTTP/1.1" 500 83578
[2019-12-06 22:50:59,610] [ERROR] [handle_uncaught_exception] : Internal Server Error: /web_index/
Traceback (most recent call last):
  File "/Library/Frameworks/Python.framework/Versions/3.6/lib/python3.6/site-packages/django/core/handlers/exception.py", line 41, in inner
    response = get_response(request)
  File "/Library/Frameworks/Python.framework/Versions/3.6/lib/python3.6/site-packages/django/core/handlers/base.py", line 187, in _get_response
    response = self.process_exception_by_middleware(e, request)
  File "/Library/Frameworks/Python.framework/Versions/3.6/lib/python3.6/site-packages/django/core/handlers/base.py", line 185, in _get_response
    response = wrapped_callback(request, *callback_args, **callback_kwargs)
  File "/Library/Frameworks/Python.framework/Versions/3.6/lib/python3.6/site-packages/django/contrib/auth/decorators.py", line 23, in _wrapped_view
    return view_func(request, *args, **kwargs)
  File "/Users/zhuzhanhao/Testapi/Api/views.py", line 69, in web_index_views
    return render(request, 'static/index.html')
  File "/Library/Frameworks/Python.framework/Versions/3.6/lib/python3.6/site-packages/django/shortcuts.py", line 30, in render
    content = loader.render_to_string(template_name, context, request, using=using)
  File "/Library/Frameworks/Python.framework/Versions/3.6/lib/python3.6/site-packages/django/template/loader.py", line 67, in render_to_string
    template = get_template(template_name, using=using)
  File "/Library/Frameworks/Python.framework/Versions/3.6/lib/python3.6/site-packages/django/template/loader.py", line 25, in get_template
    raise TemplateDoesNotExist(template_name, chain=chain)
django.template.exceptions.TemplateDoesNotExist: static/index.html
[2019-12-06 22:50:59,686] [ERROR] [log_message] : "GET /web_index/ HTTP/1.1" 500 83593
[2019-12-06 22:53:04,992] [WARNING] [get_response] : Not Found: /web_index/.static.images.json
[2019-12-06 22:53:04,994] [WARNING] [log_message] : "GET /web_index/.static.images.json HTTP/1.1" 404 11292
[2019-12-06 22:53:09,433] [WARNING] [get_response] : Not Found: /web_index/.static.images.json
[2019-12-06 22:53:09,433] [WARNING] [log_message] : "GET /web_index/.static.images.json HTTP/1.1" 404 11292
[2019-12-06 22:53:11,448] [WARNING] [get_response] : Not Found: /web_index/.static.images.json
[2019-12-06 22:53:11,449] [WARNING] [log_message] : "GET /web_index/.static.images.json HTTP/1.1" 404 11292
[2019-12-06 22:53:48,837] [WARNING] [get_response] : Not Found: /web_index/.static.images.json
[2019-12-06 22:53:48,838] [WARNING] [log_message] : "GET /web_index/.static.images.json HTTP/1.1" 404 11292
[2019-12-06 22:57:16,040] [WARNING] [get_response] : Not Found: /web_index/.static.images.json
[2019-12-06 22:57:16,044] [WARNING] [log_message] : "GET /web_index/.static.images.json HTTP/1.1" 404 11292
[2019-12-06 22:57:16,583] [WARNING] [get_response] : Not Found: /web_index/.static.images.json
[2019-12-06 22:57:16,583] [WARNING] [log_message] : "GET /web_index/.static.images.json HTTP/1.1" 404 11292
[2019-12-06 23:01:05,799] [WARNING] [get_response] : Not Found: /Web/static/layui/css/layui.css
[2019-12-06 23:01:05,818] [WARNING] [log_message] : "GET /Web/static/layui/css/layui.css HTTP/1.1" 404 11295
[2019-12-06 23:01:05,817] [WARNING] [get_response] : Not Found: /Web/static/layui/layui.js
[2019-12-06 23:01:05,821] [WARNING] [log_message] : "GET /Web/static/layui/layui.js HTTP/1.1" 404 11280
[2019-12-06 23:01:13,746] [WARNING] [get_response] : Not Found: /Web/static/layui/css/layui.css
[2019-12-06 23:01:13,753] [WARNING] [log_message] : "GET /Web/static/layui/css/layui.css HTTP/1.1" 404 11295
[2019-12-06 23:01:13,765] [WARNING] [get_response] : Not Found: /Web/static/layui/layui.js
[2019-12-06 23:01:13,765] [WARNING] [log_message] : "GET /Web/static/layui/layui.js HTTP/1.1" 404 11280
[2019-12-06 23:02:17,231] [WARNING] [get_response] : Not Found: /Web/static/layui/css/layui.css
[2019-12-06 23:02:17,243] [WARNING] [get_response] : Not Found: /Web/static/layui/layui.js
[2019-12-06 23:02:17,244] [WARNING] [log_message] : "GET /Web/static/layui/css/layui.css HTTP/1.1" 404 11295
[2019-12-06 23:02:17,245] [WARNING] [log_message] : "GET /Web/static/layui/layui.js HTTP/1.1" 404 11280
[2019-12-06 23:04:22,333] [WARNING] [get_response] : Not Found: /Web/static/layui/css/layui.css
[2019-12-06 23:04:22,334] [WARNING] [get_response] : Not Found: /Web/static/layui/layui.js
[2019-12-06 23:04:22,335] [WARNING] [log_message] : "GET /Web/static/layui/layui.js HTTP/1.1" 404 11280
[2019-12-06 23:04:22,348] [WARNING] [log_message] : "GET /Web/static/layui/css/layui.css HTTP/1.1" 404 11295
[2019-12-06 23:04:25,829] [WARNING] [get_response] : Not Found: /Web/static/layui/css/layui.css
[2019-12-06 23:04:25,832] [WARNING] [log_message] : "GET /Web/static/layui/css/layui.css HTTP/1.1" 404 11295
[2019-12-06 23:04:25,853] [WARNING] [get_response] : Not Found: /Web/static/layui/layui.js
[2019-12-06 23:04:25,854] [WARNING] [log_message] : "GET /Web/static/layui/layui.js HTTP/1.1" 404 11280
[2019-12-06 23:04:28,791] [WARNING] [get_response] : Not Found: /web_linklist/.static.images.json
[2019-12-06 23:04:28,792] [WARNING] [log_message] : "GET /web_linklist/.static.images.json?page=1&limit=20 HTTP/1.1" 404 11321
[2019-12-06 23:05:13,426] [WARNING] [get_response] : Not Found: /Web/static/layui/css/layui.css
[2019-12-06 23:05:13,442] [WARNING] [get_response] : Not Found: /Web/static/layui/layui.js
[2019-12-06 23:05:13,443] [WARNING] [log_message] : "GET /Web/static/layui/css/layui.css HTTP/1.1" 404 11295
[2019-12-06 23:05:13,443] [WARNING] [log_message] : "GET /Web/static/layui/layui.js HTTP/1.1" 404 11280
[2019-12-06 23:23:04,419] [WARNING] [log_message] : "GET /static/images/login_bg.jpg HTTP/1.1" 404 1670
[2019-12-06 23:34:43,585] [WARNING] [get_response] : Not Found: /favicon.ico
[2019-12-06 23:34:43,588] [WARNING] [log_message] : "GET /favicon.ico HTTP/1.1" 404 11238
[2019-12-07 00:15:21,963] [WARNING] [get_response] : Not Found: /web_info/.static.images.json
[2019-12-07 00:15:21,967] [WARNING] [log_message] : "GET /web_info/.static.images.json HTTP/1.1" 404 11289
[2019-12-07 00:27:28,719] [ERROR] [handle_uncaught_exception] : Internal Server Error: /apilist/
Traceback (most recent call last):
  File "/Library/Frameworks/Python.framework/Versions/3.6/lib/python3.6/site-packages/django/core/handlers/exception.py", line 41, in inner
    response = get_response(request)
  File "/Library/Frameworks/Python.framework/Versions/3.6/lib/python3.6/site-packages/django/core/handlers/base.py", line 187, in _get_response
    response = self.process_exception_by_middleware(e, request)
  File "/Library/Frameworks/Python.framework/Versions/3.6/lib/python3.6/site-packages/django/core/handlers/base.py", line 185, in _get_response
    response = wrapped_callback(request, *callback_args, **callback_kwargs)
  File "/Users/zhuzhanhao/Testapi/Api/api/view_api.py", line 145, in apilist_view
    apilists = Case.objects.filter(Q(belong__contains="库房接口") & Q(system="tdr")).order_by("sortid")
NameError: name 'Case' is not defined
[2019-12-07 00:27:29,628] [ERROR] [log_message] : "GET /apilist/?page=1&limit=30&belong=warehouse&system=tdr HTTP/1.1" 500 14876
[2019-12-07 14:01:33,225] [WARNING] [log_message] : "GET /static/images/login_bg.jpg HTTP/1.1" 404 1670
[2019-12-07 16:35:50,130] [WARNING] [log_message] : "GET /static/images/login_bg.jpg HTTP/1.1" 404 1670
[2019-12-07 16:44:34,869] [WARNING] [log_message] : "GET /static/images/login_bg.jpg HTTP/1.1" 404 1670
[2019-12-07 18:24:23,019] [ERROR] [handle_uncaught_exception] : Internal Server Error: /show_progress/
Traceback (most recent call last):
  File "/Library/Frameworks/Python.framework/Versions/3.6/lib/python3.6/site-packages/django/core/handlers/exception.py", line 41, in inner
    response = get_response(request)
  File "/Library/Frameworks/Python.framework/Versions/3.6/lib/python3.6/site-packages/django/core/handlers/base.py", line 187, in _get_response
    response = self.process_exception_by_middleware(e, request)
  File "/Library/Frameworks/Python.framework/Versions/3.6/lib/python3.6/site-packages/django/core/handlers/base.py", line 185, in _get_response
    response = wrapped_callback(request, *callback_args, **callback_kwargs)
  File "/Library/Frameworks/Python.framework/Versions/3.6/lib/python3.6/site-packages/django/contrib/auth/decorators.py", line 23, in _wrapped_view
    return view_func(request, *args, **kwargs)
  File "/Users/zhuzhanhao/Testapi/Api/api/view_process.py", line 726, in show_progress_views
    return HttpResponse(num_progress, safe=False)
  File "/Library/Frameworks/Python.framework/Versions/3.6/lib/python3.6/site-packages/django/http/response.py", line 301, in __init__
    super(HttpResponse, self).__init__(*args, **kwargs)
TypeError: __init__() got an unexpected keyword argument 'safe'
[2019-12-07 18:24:23,113] [ERROR] [log_message] : "GET /show_progress/ HTTP/1.1" 500 15137
[2019-12-07 18:24:23,268] [ERROR] [handle_uncaught_exception] : Internal Server Error: /show_progress/
Traceback (most recent call last):
  File "/Library/Frameworks/Python.framework/Versions/3.6/lib/python3.6/site-packages/django/core/handlers/exception.py", line 41, in inner
    response = get_response(request)
  File "/Library/Frameworks/Python.framework/Versions/3.6/lib/python3.6/site-packages/django/core/handlers/base.py", line 187, in _get_response
    response = self.process_exception_by_middleware(e, request)
  File "/Library/Frameworks/Python.framework/Versions/3.6/lib/python3.6/site-packages/django/core/handlers/base.py", line 185, in _get_response
    response = wrapped_callback(request, *callback_args, **callback_kwargs)
  File "/Library/Frameworks/Python.framework/Versions/3.6/lib/python3.6/site-packages/django/contrib/auth/decorators.py", line 23, in _wrapped_view
    return view_func(request, *args, **kwargs)
  File "/Users/zhuzhanhao/Testapi/Api/api/view_process.py", line 726, in show_progress_views
    return HttpResponse(num_progress, safe=False)
  File "/Library/Frameworks/Python.framework/Versions/3.6/lib/python3.6/site-packages/django/http/response.py", line 301, in __init__
    super(HttpResponse, self).__init__(*args, **kwargs)
TypeError: __init__() got an unexpected keyword argument 'safe'
[2019-12-07 18:24:23,294] [ERROR] [log_message] : "GET /show_progress/ HTTP/1.1" 500 15137
[2019-12-07 18:24:23,524] [ERROR] [handle_uncaught_exception] : Internal Server Error: /show_progress/
Traceback (most recent call last):
  File "/Library/Frameworks/Python.framework/Versions/3.6/lib/python3.6/site-packages/django/core/handlers/exception.py", line 41, in inner
    response = get_response(request)
  File "/Library/Frameworks/Python.framework/Versions/3.6/lib/python3.6/site-packages/django/core/handlers/base.py", line 187, in _get_response
    response = self.process_exception_by_middleware(e, request)
  File "/Library/Frameworks/Python.framework/Versions/3.6/lib/python3.6/site-packages/django/core/handlers/base.py", line 185, in _get_response
    response = wrapped_callback(request, *callback_args, **callback_kwargs)
  File "/Library/Frameworks/Python.framework/Versions/3.6/lib/python3.6/site-packages/django/contrib/auth/decorators.py", line 23, in _wrapped_view
    return view_func(request, *args, **kwargs)
  File "/Users/zhuzhanhao/Testapi/Api/api/view_process.py", line 726, in show_progress_views
    return HttpResponse(num_progress, safe=False)
  File "/Library/Frameworks/Python.framework/Versions/3.6/lib/python3.6/site-packages/django/http/response.py", line 301, in __init__
    super(HttpResponse, self).__init__(*args, **kwargs)
TypeError: __init__() got an unexpected keyword argument 'safe'
[2019-12-07 18:24:23,553] [ERROR] [log_message] : "GET /show_progress/ HTTP/1.1" 500 15137
[2019-12-07 18:24:23,774] [ERROR] [handle_uncaught_exception] : Internal Server Error: /show_progress/
Traceback (most recent call last):
  File "/Library/Frameworks/Python.framework/Versions/3.6/lib/python3.6/site-packages/django/core/handlers/exception.py", line 41, in inner
    response = get_response(request)
  File "/Library/Frameworks/Python.framework/Versions/3.6/lib/python3.6/site-packages/django/core/handlers/base.py", line 187, in _get_response
    response = self.process_exception_by_middleware(e, request)
  File "/Library/Frameworks/Python.framework/Versions/3.6/lib/python3.6/site-packages/django/core/handlers/base.py", line 185, in _get_response
    response = wrapped_callback(request, *callback_args, **callback_kwargs)
  File "/Library/Frameworks/Python.framework/Versions/3.6/lib/python3.6/site-packages/django/contrib/auth/decorators.py", line 23, in _wrapped_view
    return view_func(request, *args, **kwargs)
  File "/Users/zhuzhanhao/Testapi/Api/api/view_process.py", line 726, in show_progress_views
    return HttpResponse(num_progress, safe=False)
  File "/Library/Frameworks/Python.framework/Versions/3.6/lib/python3.6/site-packages/django/http/response.py", line 301, in __init__
    super(HttpResponse, self).__init__(*args, **kwargs)
TypeError: __init__() got an unexpected keyword argument 'safe'
[2019-12-07 18:24:23,802] [ERROR] [log_message] : "GET /show_progress/ HTTP/1.1" 500 15137
[2019-12-07 18:24:24,024] [ERROR] [handle_uncaught_exception] : Internal Server Error: /show_progress/
Traceback (most recent call last):
  File "/Library/Frameworks/Python.framework/Versions/3.6/lib/python3.6/site-packages/django/core/handlers/exception.py", line 41, in inner
    response = get_response(request)
  File "/Library/Frameworks/Python.framework/Versions/3.6/lib/python3.6/site-packages/django/core/handlers/base.py", line 187, in _get_response
    response = self.process_exception_by_middleware(e, request)
  File "/Library/Frameworks/Python.framework/Versions/3.6/lib/python3.6/site-packages/django/core/handlers/base.py", line 185, in _get_response
    response = wrapped_callback(request, *callback_args, **callback_kwargs)
  File "/Library/Frameworks/Python.framework/Versions/3.6/lib/python3.6/site-packages/django/contrib/auth/decorators.py", line 23, in _wrapped_view
    return view_func(request, *args, **kwargs)
  File "/Users/zhuzhanhao/Testapi/Api/api/view_process.py", line 726, in show_progress_views
    return HttpResponse(num_progress, safe=False)
  File "/Library/Frameworks/Python.framework/Versions/3.6/lib/python3.6/site-packages/django/http/response.py", line 301, in __init__
    super(HttpResponse, self).__init__(*args, **kwargs)
TypeError: __init__() got an unexpected keyword argument 'safe'
[2019-12-07 18:24:24,052] [ERROR] [log_message] : "GET /show_progress/ HTTP/1.1" 500 15137
[2019-12-07 18:24:24,269] [ERROR] [handle_uncaught_exception] : Internal Server Error: /show_progress/
Traceback (most recent call last):
  File "/Library/Frameworks/Python.framework/Versions/3.6/lib/python3.6/site-packages/django/core/handlers/exception.py", line 41, in inner
    response = get_response(request)
  File "/Library/Frameworks/Python.framework/Versions/3.6/lib/python3.6/site-packages/django/core/handlers/base.py", line 187, in _get_response
    response = self.process_exception_by_middleware(e, request)
  File "/Library/Frameworks/Python.framework/Versions/3.6/lib/python3.6/site-packages/django/core/handlers/base.py", line 185, in _get_response
    response = wrapped_callback(request, *callback_args, **callback_kwargs)
  File "/Library/Frameworks/Python.framework/Versions/3.6/lib/python3.6/site-packages/django/contrib/auth/decorators.py", line 23, in _wrapped_view
    return view_func(request, *args, **kwargs)
  File "/Users/zhuzhanhao/Testapi/Api/api/view_process.py", line 726, in show_progress_views
    return HttpResponse(num_progress, safe=False)
  File "/Library/Frameworks/Python.framework/Versions/3.6/lib/python3.6/site-packages/django/http/response.py", line 301, in __init__
    super(HttpResponse, self).__init__(*args, **kwargs)
TypeError: __init__() got an unexpected keyword argument 'safe'
[2019-12-07 18:24:24,301] [ERROR] [log_message] : "GET /show_progress/ HTTP/1.1" 500 15137
[2019-12-07 18:24:24,527] [ERROR] [handle_uncaught_exception] : Internal Server Error: /show_progress/
Traceback (most recent call last):
  File "/Library/Frameworks/Python.framework/Versions/3.6/lib/python3.6/site-packages/django/core/handlers/exception.py", line 41, in inner
    response = get_response(request)
  File "/Library/Frameworks/Python.framework/Versions/3.6/lib/python3.6/site-packages/django/core/handlers/base.py", line 187, in _get_response
    response = self.process_exception_by_middleware(e, request)
  File "/Library/Frameworks/Python.framework/Versions/3.6/lib/python3.6/site-packages/django/core/handlers/base.py", line 185, in _get_response
    response = wrapped_callback(request, *callback_args, **callback_kwargs)
  File "/Library/Frameworks/Python.framework/Versions/3.6/lib/python3.6/site-packages/django/contrib/auth/decorators.py", line 23, in _wrapped_view
    return view_func(request, *args, **kwargs)
  File "/Users/zhuzhanhao/Testapi/Api/api/view_process.py", line 726, in show_progress_views
    return HttpResponse(num_progress, safe=False)
  File "/Library/Frameworks/Python.framework/Versions/3.6/lib/python3.6/site-packages/django/http/response.py", line 301, in __init__
    super(HttpResponse, self).__init__(*args, **kwargs)
TypeError: __init__() got an unexpected keyword argument 'safe'
[2019-12-07 18:24:24,588] [ERROR] [log_message] : "GET /show_progress/ HTTP/1.1" 500 15137
[2019-12-07 18:24:24,780] [ERROR] [handle_uncaught_exception] : Internal Server Error: /show_progress/
Traceback (most recent call last):
  File "/Library/Frameworks/Python.framework/Versions/3.6/lib/python3.6/site-packages/django/core/handlers/exception.py", line 41, in inner
    response = get_response(request)
  File "/Library/Frameworks/Python.framework/Versions/3.6/lib/python3.6/site-packages/django/core/handlers/base.py", line 187, in _get_response
    response = self.process_exception_by_middleware(e, request)
  File "/Library/Frameworks/Python.framework/Versions/3.6/lib/python3.6/site-packages/django/core/handlers/base.py", line 185, in _get_response
    response = wrapped_callback(request, *callback_args, **callback_kwargs)
  File "/Library/Frameworks/Python.framework/Versions/3.6/lib/python3.6/site-packages/django/contrib/auth/decorators.py", line 23, in _wrapped_view
    return view_func(request, *args, **kwargs)
  File "/Users/zhuzhanhao/Testapi/Api/api/view_process.py", line 726, in show_progress_views
    return HttpResponse(num_progress, safe=False)
  File "/Library/Frameworks/Python.framework/Versions/3.6/lib/python3.6/site-packages/django/http/response.py", line 301, in __init__
    super(HttpResponse, self).__init__(*args, **kwargs)
TypeError: __init__() got an unexpected keyword argument 'safe'
[2019-12-07 18:24:24,813] [ERROR] [log_message] : "GET /show_progress/ HTTP/1.1" 500 15137
[2019-12-07 18:24:25,012] [ERROR] [handle_uncaught_exception] : Internal Server Error: /show_progress/
Traceback (most recent call last):
  File "/Library/Frameworks/Python.framework/Versions/3.6/lib/python3.6/site-packages/django/core/handlers/exception.py", line 41, in inner
    response = get_response(request)
  File "/Library/Frameworks/Python.framework/Versions/3.6/lib/python3.6/site-packages/django/core/handlers/base.py", line 187, in _get_response
    response = self.process_exception_by_middleware(e, request)
  File "/Library/Frameworks/Python.framework/Versions/3.6/lib/python3.6/site-packages/django/core/handlers/base.py", line 185, in _get_response
    response = wrapped_callback(request, *callback_args, **callback_kwargs)
  File "/Library/Frameworks/Python.framework/Versions/3.6/lib/python3.6/site-packages/django/contrib/auth/decorators.py", line 23, in _wrapped_view
    return view_func(request, *args, **kwargs)
  File "/Users/zhuzhanhao/Testapi/Api/api/view_process.py", line 726, in show_progress_views
    return HttpResponse(num_progress, safe=False)
  File "/Library/Frameworks/Python.framework/Versions/3.6/lib/python3.6/site-packages/django/http/response.py", line 301, in __init__
    super(HttpResponse, self).__init__(*args, **kwargs)
TypeError: __init__() got an unexpected keyword argument 'safe'
[2019-12-07 18:24:25,042] [ERROR] [log_message] : "GET /show_progress/ HTTP/1.1" 500 15137
[2019-12-07 18:24:25,270] [ERROR] [handle_uncaught_exception] : Internal Server Error: /show_progress/
Traceback (most recent call last):
  File "/Library/Frameworks/Python.framework/Versions/3.6/lib/python3.6/site-packages/django/core/handlers/exception.py", line 41, in inner
    response = get_response(request)
  File "/Library/Frameworks/Python.framework/Versions/3.6/lib/python3.6/site-packages/django/core/handlers/base.py", line 187, in _get_response
    response = self.process_exception_by_middleware(e, request)
  File "/Library/Frameworks/Python.framework/Versions/3.6/lib/python3.6/site-packages/django/core/handlers/base.py", line 185, in _get_response
    response = wrapped_callback(request, *callback_args, **callback_kwargs)
  File "/Library/Frameworks/Python.framework/Versions/3.6/lib/python3.6/site-packages/django/contrib/auth/decorators.py", line 23, in _wrapped_view
    return view_func(request, *args, **kwargs)
  File "/Users/zhuzhanhao/Testapi/Api/api/view_process.py", line 723, in show_progress_views
    return HttpResponse(100, safe=False)
  File "/Library/Frameworks/Python.framework/Versions/3.6/lib/python3.6/site-packages/django/http/response.py", line 301, in __init__
    super(HttpResponse, self).__init__(*args, **kwargs)
TypeError: __init__() got an unexpected keyword argument 'safe'
[2019-12-07 18:24:25,303] [ERROR] [log_message] : "GET /show_progress/ HTTP/1.1" 500 15128
[2019-12-07 18:24:25,538] [ERROR] [handle_uncaught_exception] : Internal Server Error: /show_progress/
Traceback (most recent call last):
  File "/Library/Frameworks/Python.framework/Versions/3.6/lib/python3.6/site-packages/django/core/handlers/exception.py", line 41, in inner
    response = get_response(request)
  File "/Library/Frameworks/Python.framework/Versions/3.6/lib/python3.6/site-packages/django/core/handlers/base.py", line 187, in _get_response
    response = self.process_exception_by_middleware(e, request)
  File "/Library/Frameworks/Python.framework/Versions/3.6/lib/python3.6/site-packages/django/core/handlers/base.py", line 185, in _get_response
    response = wrapped_callback(request, *callback_args, **callback_kwargs)
  File "/Library/Frameworks/Python.framework/Versions/3.6/lib/python3.6/site-packages/django/contrib/auth/decorators.py", line 23, in _wrapped_view
    return view_func(request, *args, **kwargs)
  File "/Users/zhuzhanhao/Testapi/Api/api/view_process.py", line 726, in show_progress_views
    return HttpResponse(num_progress, safe=False)
  File "/Library/Frameworks/Python.framework/Versions/3.6/lib/python3.6/site-packages/django/http/response.py", line 301, in __init__
    super(HttpResponse, self).__init__(*args, **kwargs)
TypeError: __init__() got an unexpected keyword argument 'safe'
[2019-12-07 18:24:25,568] [ERROR] [log_message] : "GET /show_progress/ HTTP/1.1" 500 15136
[2019-12-07 18:24:25,768] [ERROR] [handle_uncaught_exception] : Internal Server Error: /show_progress/
Traceback (most recent call last):
  File "/Library/Frameworks/Python.framework/Versions/3.6/lib/python3.6/site-packages/django/core/handlers/exception.py", line 41, in inner
    response = get_response(request)
  File "/Library/Frameworks/Python.framework/Versions/3.6/lib/python3.6/site-packages/django/core/handlers/base.py", line 187, in _get_response
    response = self.process_exception_by_middleware(e, request)
  File "/Library/Frameworks/Python.framework/Versions/3.6/lib/python3.6/site-packages/django/core/handlers/base.py", line 185, in _get_response
    response = wrapped_callback(request, *callback_args, **callback_kwargs)
  File "/Library/Frameworks/Python.framework/Versions/3.6/lib/python3.6/site-packages/django/contrib/auth/decorators.py", line 23, in _wrapped_view
    return view_func(request, *args, **kwargs)
  File "/Users/zhuzhanhao/Testapi/Api/api/view_process.py", line 726, in show_progress_views
    return HttpResponse(num_progress, safe=False)
  File "/Library/Frameworks/Python.framework/Versions/3.6/lib/python3.6/site-packages/django/http/response.py", line 301, in __init__
    super(HttpResponse, self).__init__(*args, **kwargs)
TypeError: __init__() got an unexpected keyword argument 'safe'
[2019-12-07 18:24:25,790] [ERROR] [log_message] : "GET /show_progress/ HTTP/1.1" 500 15136
[2019-12-07 18:24:26,016] [ERROR] [handle_uncaught_exception] : Internal Server Error: /show_progress/
Traceback (most recent call last):
  File "/Library/Frameworks/Python.framework/Versions/3.6/lib/python3.6/site-packages/django/core/handlers/exception.py", line 41, in inner
    response = get_response(request)
  File "/Library/Frameworks/Python.framework/Versions/3.6/lib/python3.6/site-packages/django/core/handlers/base.py", line 187, in _get_response
    response = self.process_exception_by_middleware(e, request)
  File "/Library/Frameworks/Python.framework/Versions/3.6/lib/python3.6/site-packages/django/core/handlers/base.py", line 185, in _get_response
    response = wrapped_callback(request, *callback_args, **callback_kwargs)
  File "/Library/Frameworks/Python.framework/Versions/3.6/lib/python3.6/site-packages/django/contrib/auth/decorators.py", line 23, in _wrapped_view
    return view_func(request, *args, **kwargs)
  File "/Users/zhuzhanhao/Testapi/Api/api/view_process.py", line 726, in show_progress_views
    return HttpResponse(num_progress, safe=False)
  File "/Library/Frameworks/Python.framework/Versions/3.6/lib/python3.6/site-packages/django/http/response.py", line 301, in __init__
    super(HttpResponse, self).__init__(*args, **kwargs)
TypeError: __init__() got an unexpected keyword argument 'safe'
[2019-12-07 18:24:26,034] [ERROR] [log_message] : "GET /show_progress/ HTTP/1.1" 500 15136
[2019-12-07 18:24:26,269] [ERROR] [handle_uncaught_exception] : Internal Server Error: /show_progress/
Traceback (most recent call last):
  File "/Library/Frameworks/Python.framework/Versions/3.6/lib/python3.6/site-packages/django/core/handlers/exception.py", line 41, in inner
    response = get_response(request)
  File "/Library/Frameworks/Python.framework/Versions/3.6/lib/python3.6/site-packages/django/core/handlers/base.py", line 187, in _get_response
    response = self.process_exception_by_middleware(e, request)
  File "/Library/Frameworks/Python.framework/Versions/3.6/lib/python3.6/site-packages/django/core/handlers/base.py", line 185, in _get_response
    response = wrapped_callback(request, *callback_args, **callback_kwargs)
  File "/Library/Frameworks/Python.framework/Versions/3.6/lib/python3.6/site-packages/django/contrib/auth/decorators.py", line 23, in _wrapped_view
    return view_func(request, *args, **kwargs)
  File "/Users/zhuzhanhao/Testapi/Api/api/view_process.py", line 726, in show_progress_views
    return HttpResponse(num_progress, safe=False)
  File "/Library/Frameworks/Python.framework/Versions/3.6/lib/python3.6/site-packages/django/http/response.py", line 301, in __init__
    super(HttpResponse, self).__init__(*args, **kwargs)
TypeError: __init__() got an unexpected keyword argument 'safe'
[2019-12-07 18:24:26,297] [ERROR] [log_message] : "GET /show_progress/ HTTP/1.1" 500 15136
[2019-12-07 18:24:26,531] [ERROR] [handle_uncaught_exception] : Internal Server Error: /show_progress/
Traceback (most recent call last):
  File "/Library/Frameworks/Python.framework/Versions/3.6/lib/python3.6/site-packages/django/core/handlers/exception.py", line 41, in inner
    response = get_response(request)
  File "/Library/Frameworks/Python.framework/Versions/3.6/lib/python3.6/site-packages/django/core/handlers/base.py", line 187, in _get_response
    response = self.process_exception_by_middleware(e, request)
  File "/Library/Frameworks/Python.framework/Versions/3.6/lib/python3.6/site-packages/django/core/handlers/base.py", line 185, in _get_response
    response = wrapped_callback(request, *callback_args, **callback_kwargs)
  File "/Library/Frameworks/Python.framework/Versions/3.6/lib/python3.6/site-packages/django/contrib/auth/decorators.py", line 23, in _wrapped_view
    return view_func(request, *args, **kwargs)
  File "/Users/zhuzhanhao/Testapi/Api/api/view_process.py", line 726, in show_progress_views
    return HttpResponse(num_progress, safe=False)
  File "/Library/Frameworks/Python.framework/Versions/3.6/lib/python3.6/site-packages/django/http/response.py", line 301, in __init__
    super(HttpResponse, self).__init__(*args, **kwargs)
TypeError: __init__() got an unexpected keyword argument 'safe'
[2019-12-07 18:24:26,551] [ERROR] [log_message] : "GET /show_progress/ HTTP/1.1" 500 15136
[2019-12-07 18:24:26,778] [ERROR] [handle_uncaught_exception] : Internal Server Error: /show_progress/
Traceback (most recent call last):
  File "/Library/Frameworks/Python.framework/Versions/3.6/lib/python3.6/site-packages/django/core/handlers/exception.py", line 41, in inner
    response = get_response(request)
  File "/Library/Frameworks/Python.framework/Versions/3.6/lib/python3.6/site-packages/django/core/handlers/base.py", line 187, in _get_response
    response = self.process_exception_by_middleware(e, request)
  File "/Library/Frameworks/Python.framework/Versions/3.6/lib/python3.6/site-packages/django/core/handlers/base.py", line 185, in _get_response
    response = wrapped_callback(request, *callback_args, **callback_kwargs)
  File "/Library/Frameworks/Python.framework/Versions/3.6/lib/python3.6/site-packages/django/contrib/auth/decorators.py", line 23, in _wrapped_view
    return view_func(request, *args, **kwargs)
  File "/Users/zhuzhanhao/Testapi/Api/api/view_process.py", line 726, in show_progress_views
    return HttpResponse(num_progress, safe=False)
  File "/Library/Frameworks/Python.framework/Versions/3.6/lib/python3.6/site-packages/django/http/response.py", line 301, in __init__
    super(HttpResponse, self).__init__(*args, **kwargs)
TypeError: __init__() got an unexpected keyword argument 'safe'
[2019-12-07 18:24:26,800] [ERROR] [log_message] : "GET /show_progress/ HTTP/1.1" 500 15136
[2019-12-07 18:24:27,023] [ERROR] [handle_uncaught_exception] : Internal Server Error: /show_progress/
Traceback (most recent call last):
  File "/Library/Frameworks/Python.framework/Versions/3.6/lib/python3.6/site-packages/django/core/handlers/exception.py", line 41, in inner
    response = get_response(request)
  File "/Library/Frameworks/Python.framework/Versions/3.6/lib/python3.6/site-packages/django/core/handlers/base.py", line 187, in _get_response
    response = self.process_exception_by_middleware(e, request)
  File "/Library/Frameworks/Python.framework/Versions/3.6/lib/python3.6/site-packages/django/core/handlers/base.py", line 185, in _get_response
    response = wrapped_callback(request, *callback_args, **callback_kwargs)
  File "/Library/Frameworks/Python.framework/Versions/3.6/lib/python3.6/site-packages/django/contrib/auth/decorators.py", line 23, in _wrapped_view
    return view_func(request, *args, **kwargs)
  File "/Users/zhuzhanhao/Testapi/Api/api/view_process.py", line 726, in show_progress_views
    return HttpResponse(num_progress, safe=False)
  File "/Library/Frameworks/Python.framework/Versions/3.6/lib/python3.6/site-packages/django/http/response.py", line 301, in __init__
    super(HttpResponse, self).__init__(*args, **kwargs)
TypeError: __init__() got an unexpected keyword argument 'safe'
[2019-12-07 18:24:27,040] [ERROR] [log_message] : "GET /show_progress/ HTTP/1.1" 500 15136
[2019-12-07 18:24:27,264] [ERROR] [handle_uncaught_exception] : Internal Server Error: /show_progress/
Traceback (most recent call last):
  File "/Library/Frameworks/Python.framework/Versions/3.6/lib/python3.6/site-packages/django/core/handlers/exception.py", line 41, in inner
    response = get_response(request)
  File "/Library/Frameworks/Python.framework/Versions/3.6/lib/python3.6/site-packages/django/core/handlers/base.py", line 187, in _get_response
    response = self.process_exception_by_middleware(e, request)
  File "/Library/Frameworks/Python.framework/Versions/3.6/lib/python3.6/site-packages/django/core/handlers/base.py", line 185, in _get_response
    response = wrapped_callback(request, *callback_args, **callback_kwargs)
  File "/Library/Frameworks/Python.framework/Versions/3.6/lib/python3.6/site-packages/django/contrib/auth/decorators.py", line 23, in _wrapped_view
    return view_func(request, *args, **kwargs)
  File "/Users/zhuzhanhao/Testapi/Api/api/view_process.py", line 726, in show_progress_views
    return HttpResponse(num_progress, safe=False)
  File "/Library/Frameworks/Python.framework/Versions/3.6/lib/python3.6/site-packages/django/http/response.py", line 301, in __init__
    super(HttpResponse, self).__init__(*args, **kwargs)
TypeError: __init__() got an unexpected keyword argument 'safe'
[2019-12-07 18:24:27,287] [ERROR] [log_message] : "GET /show_progress/ HTTP/1.1" 500 15136
[2019-12-07 18:24:27,529] [ERROR] [handle_uncaught_exception] : Internal Server Error: /show_progress/
Traceback (most recent call last):
  File "/Library/Frameworks/Python.framework/Versions/3.6/lib/python3.6/site-packages/django/core/handlers/exception.py", line 41, in inner
    response = get_response(request)
  File "/Library/Frameworks/Python.framework/Versions/3.6/lib/python3.6/site-packages/django/core/handlers/base.py", line 187, in _get_response
    response = self.process_exception_by_middleware(e, request)
  File "/Library/Frameworks/Python.framework/Versions/3.6/lib/python3.6/site-packages/django/core/handlers/base.py", line 185, in _get_response
    response = wrapped_callback(request, *callback_args, **callback_kwargs)
  File "/Library/Frameworks/Python.framework/Versions/3.6/lib/python3.6/site-packages/django/contrib/auth/decorators.py", line 23, in _wrapped_view
    return view_func(request, *args, **kwargs)
  File "/Users/zhuzhanhao/Testapi/Api/api/view_process.py", line 726, in show_progress_views
    return HttpResponse(num_progress, safe=False)
  File "/Library/Frameworks/Python.framework/Versions/3.6/lib/python3.6/site-packages/django/http/response.py", line 301, in __init__
    super(HttpResponse, self).__init__(*args, **kwargs)
TypeError: __init__() got an unexpected keyword argument 'safe'
[2019-12-07 18:24:27,570] [ERROR] [log_message] : "GET /show_progress/ HTTP/1.1" 500 15136
[2019-12-07 18:24:27,818] [ERROR] [handle_uncaught_exception] : Internal Server Error: /show_progress/
Traceback (most recent call last):
  File "/Library/Frameworks/Python.framework/Versions/3.6/lib/python3.6/site-packages/django/core/handlers/exception.py", line 41, in inner
    response = get_response(request)
  File "/Library/Frameworks/Python.framework/Versions/3.6/lib/python3.6/site-packages/django/core/handlers/base.py", line 187, in _get_response
    response = self.process_exception_by_middleware(e, request)
  File "/Library/Frameworks/Python.framework/Versions/3.6/lib/python3.6/site-packages/django/core/handlers/base.py", line 185, in _get_response
    response = wrapped_callback(request, *callback_args, **callback_kwargs)
  File "/Library/Frameworks/Python.framework/Versions/3.6/lib/python3.6/site-packages/django/contrib/auth/decorators.py", line 23, in _wrapped_view
    return view_func(request, *args, **kwargs)
  File "/Users/zhuzhanhao/Testapi/Api/api/view_process.py", line 726, in show_progress_views
    return HttpResponse(num_progress, safe=False)
  File "/Library/Frameworks/Python.framework/Versions/3.6/lib/python3.6/site-packages/django/http/response.py", line 301, in __init__
    super(HttpResponse, self).__init__(*args, **kwargs)
TypeError: __init__() got an unexpected keyword argument 'safe'
[2019-12-07 18:24:27,841] [ERROR] [log_message] : "GET /show_progress/ HTTP/1.1" 500 15136
[2019-12-07 18:24:28,019] [ERROR] [handle_uncaught_exception] : Internal Server Error: /show_progress/
Traceback (most recent call last):
  File "/Library/Frameworks/Python.framework/Versions/3.6/lib/python3.6/site-packages/django/core/handlers/exception.py", line 41, in inner
    response = get_response(request)
  File "/Library/Frameworks/Python.framework/Versions/3.6/lib/python3.6/site-packages/django/core/handlers/base.py", line 187, in _get_response
    response = self.process_exception_by_middleware(e, request)
  File "/Library/Frameworks/Python.framework/Versions/3.6/lib/python3.6/site-packages/django/core/handlers/base.py", line 185, in _get_response
    response = wrapped_callback(request, *callback_args, **callback_kwargs)
  File "/Library/Frameworks/Python.framework/Versions/3.6/lib/python3.6/site-packages/django/contrib/auth/decorators.py", line 23, in _wrapped_view
    return view_func(request, *args, **kwargs)
  File "/Users/zhuzhanhao/Testapi/Api/api/view_process.py", line 726, in show_progress_views
    return HttpResponse(num_progress, safe=False)
  File "/Library/Frameworks/Python.framework/Versions/3.6/lib/python3.6/site-packages/django/http/response.py", line 301, in __init__
    super(HttpResponse, self).__init__(*args, **kwargs)
TypeError: __init__() got an unexpected keyword argument 'safe'
[2019-12-07 18:24:28,046] [ERROR] [log_message] : "GET /show_progress/ HTTP/1.1" 500 15136
[2019-12-07 18:24:28,261] [ERROR] [handle_uncaught_exception] : Internal Server Error: /show_progress/
Traceback (most recent call last):
  File "/Library/Frameworks/Python.framework/Versions/3.6/lib/python3.6/site-packages/django/core/handlers/exception.py", line 41, in inner
    response = get_response(request)
  File "/Library/Frameworks/Python.framework/Versions/3.6/lib/python3.6/site-packages/django/core/handlers/base.py", line 187, in _get_response
    response = self.process_exception_by_middleware(e, request)
  File "/Library/Frameworks/Python.framework/Versions/3.6/lib/python3.6/site-packages/django/core/handlers/base.py", line 185, in _get_response
    response = wrapped_callback(request, *callback_args, **callback_kwargs)
  File "/Library/Frameworks/Python.framework/Versions/3.6/lib/python3.6/site-packages/django/contrib/auth/decorators.py", line 23, in _wrapped_view
    return view_func(request, *args, **kwargs)
  File "/Users/zhuzhanhao/Testapi/Api/api/view_process.py", line 726, in show_progress_views
    return HttpResponse(num_progress, safe=False)
  File "/Library/Frameworks/Python.framework/Versions/3.6/lib/python3.6/site-packages/django/http/response.py", line 301, in __init__
    super(HttpResponse, self).__init__(*args, **kwargs)
TypeError: __init__() got an unexpected keyword argument 'safe'
[2019-12-07 18:24:28,283] [ERROR] [log_message] : "GET /show_progress/ HTTP/1.1" 500 15136
[2019-12-07 18:24:28,535] [ERROR] [handle_uncaught_exception] : Internal Server Error: /show_progress/
Traceback (most recent call last):
  File "/Library/Frameworks/Python.framework/Versions/3.6/lib/python3.6/site-packages/django/core/handlers/exception.py", line 41, in inner
    response = get_response(request)
  File "/Library/Frameworks/Python.framework/Versions/3.6/lib/python3.6/site-packages/django/core/handlers/base.py", line 187, in _get_response
    response = self.process_exception_by_middleware(e, request)
  File "/Library/Frameworks/Python.framework/Versions/3.6/lib/python3.6/site-packages/django/core/handlers/base.py", line 185, in _get_response
    response = wrapped_callback(request, *callback_args, **callback_kwargs)
  File "/Library/Frameworks/Python.framework/Versions/3.6/lib/python3.6/site-packages/django/contrib/auth/decorators.py", line 23, in _wrapped_view
    return view_func(request, *args, **kwargs)
  File "/Users/zhuzhanhao/Testapi/Api/api/view_process.py", line 726, in show_progress_views
    return HttpResponse(num_progress, safe=False)
  File "/Library/Frameworks/Python.framework/Versions/3.6/lib/python3.6/site-packages/django/http/response.py", line 301, in __init__
    super(HttpResponse, self).__init__(*args, **kwargs)
TypeError: __init__() got an unexpected keyword argument 'safe'
[2019-12-07 18:24:28,558] [ERROR] [log_message] : "GET /show_progress/ HTTP/1.1" 500 15136
[2019-12-07 18:24:28,771] [ERROR] [handle_uncaught_exception] : Internal Server Error: /show_progress/
Traceback (most recent call last):
  File "/Library/Frameworks/Python.framework/Versions/3.6/lib/python3.6/site-packages/django/core/handlers/exception.py", line 41, in inner
    response = get_response(request)
  File "/Library/Frameworks/Python.framework/Versions/3.6/lib/python3.6/site-packages/django/core/handlers/base.py", line 187, in _get_response
    response = self.process_exception_by_middleware(e, request)
  File "/Library/Frameworks/Python.framework/Versions/3.6/lib/python3.6/site-packages/django/core/handlers/base.py", line 185, in _get_response
    response = wrapped_callback(request, *callback_args, **callback_kwargs)
  File "/Library/Frameworks/Python.framework/Versions/3.6/lib/python3.6/site-packages/django/contrib/auth/decorators.py", line 23, in _wrapped_view
    return view_func(request, *args, **kwargs)
  File "/Users/zhuzhanhao/Testapi/Api/api/view_process.py", line 726, in show_progress_views
    return HttpResponse(num_progress, safe=False)
  File "/Library/Frameworks/Python.framework/Versions/3.6/lib/python3.6/site-packages/django/http/response.py", line 301, in __init__
    super(HttpResponse, self).__init__(*args, **kwargs)
TypeError: __init__() got an unexpected keyword argument 'safe'
[2019-12-07 18:24:28,792] [ERROR] [log_message] : "GET /show_progress/ HTTP/1.1" 500 15136
[2019-12-07 18:24:29,020] [ERROR] [handle_uncaught_exception] : Internal Server Error: /show_progress/
Traceback (most recent call last):
  File "/Library/Frameworks/Python.framework/Versions/3.6/lib/python3.6/site-packages/django/core/handlers/exception.py", line 41, in inner
    response = get_response(request)
  File "/Library/Frameworks/Python.framework/Versions/3.6/lib/python3.6/site-packages/django/core/handlers/base.py", line 187, in _get_response
    response = self.process_exception_by_middleware(e, request)
  File "/Library/Frameworks/Python.framework/Versions/3.6/lib/python3.6/site-packages/django/core/handlers/base.py", line 185, in _get_response
    response = wrapped_callback(request, *callback_args, **callback_kwargs)
  File "/Library/Frameworks/Python.framework/Versions/3.6/lib/python3.6/site-packages/django/contrib/auth/decorators.py", line 23, in _wrapped_view
    return view_func(request, *args, **kwargs)
  File "/Users/zhuzhanhao/Testapi/Api/api/view_process.py", line 726, in show_progress_views
    return HttpResponse(num_progress, safe=False)
  File "/Library/Frameworks/Python.framework/Versions/3.6/lib/python3.6/site-packages/django/http/response.py", line 301, in __init__
    super(HttpResponse, self).__init__(*args, **kwargs)
TypeError: __init__() got an unexpected keyword argument 'safe'
[2019-12-07 18:24:29,041] [ERROR] [log_message] : "GET /show_progress/ HTTP/1.1" 500 15136
[2019-12-07 18:24:29,331] [ERROR] [handle_uncaught_exception] : Internal Server Error: /show_progress/
Traceback (most recent call last):
  File "/Library/Frameworks/Python.framework/Versions/3.6/lib/python3.6/site-packages/django/core/handlers/exception.py", line 41, in inner
    response = get_response(request)
  File "/Library/Frameworks/Python.framework/Versions/3.6/lib/python3.6/site-packages/django/core/handlers/base.py", line 187, in _get_response
    response = self.process_exception_by_middleware(e, request)
  File "/Library/Frameworks/Python.framework/Versions/3.6/lib/python3.6/site-packages/django/core/handlers/base.py", line 185, in _get_response
    response = wrapped_callback(request, *callback_args, **callback_kwargs)
  File "/Library/Frameworks/Python.framework/Versions/3.6/lib/python3.6/site-packages/django/contrib/auth/decorators.py", line 23, in _wrapped_view
    return view_func(request, *args, **kwargs)
  File "/Users/zhuzhanhao/Testapi/Api/api/view_process.py", line 726, in show_progress_views
    return HttpResponse(num_progress, safe=False)
  File "/Library/Frameworks/Python.framework/Versions/3.6/lib/python3.6/site-packages/django/http/response.py", line 301, in __init__
    super(HttpResponse, self).__init__(*args, **kwargs)
TypeError: __init__() got an unexpected keyword argument 'safe'
[2019-12-07 18:24:29,360] [ERROR] [log_message] : "GET /show_progress/ HTTP/1.1" 500 15136
[2019-12-07 18:24:29,528] [ERROR] [handle_uncaught_exception] : Internal Server Error: /show_progress/
Traceback (most recent call last):
  File "/Library/Frameworks/Python.framework/Versions/3.6/lib/python3.6/site-packages/django/core/handlers/exception.py", line 41, in inner
    response = get_response(request)
  File "/Library/Frameworks/Python.framework/Versions/3.6/lib/python3.6/site-packages/django/core/handlers/base.py", line 187, in _get_response
    response = self.process_exception_by_middleware(e, request)
  File "/Library/Frameworks/Python.framework/Versions/3.6/lib/python3.6/site-packages/django/core/handlers/base.py", line 185, in _get_response
    response = wrapped_callback(request, *callback_args, **callback_kwargs)
  File "/Library/Frameworks/Python.framework/Versions/3.6/lib/python3.6/site-packages/django/contrib/auth/decorators.py", line 23, in _wrapped_view
    return view_func(request, *args, **kwargs)
  File "/Users/zhuzhanhao/Testapi/Api/api/view_process.py", line 726, in show_progress_views
    return HttpResponse(num_progress, safe=False)
  File "/Library/Frameworks/Python.framework/Versions/3.6/lib/python3.6/site-packages/django/http/response.py", line 301, in __init__
    super(HttpResponse, self).__init__(*args, **kwargs)
TypeError: __init__() got an unexpected keyword argument 'safe'
[2019-12-07 18:24:29,549] [ERROR] [log_message] : "GET /show_progress/ HTTP/1.1" 500 15136
[2019-12-07 18:24:29,783] [ERROR] [handle_uncaught_exception] : Internal Server Error: /show_progress/
Traceback (most recent call last):
  File "/Library/Frameworks/Python.framework/Versions/3.6/lib/python3.6/site-packages/django/core/handlers/exception.py", line 41, in inner
    response = get_response(request)
  File "/Library/Frameworks/Python.framework/Versions/3.6/lib/python3.6/site-packages/django/core/handlers/base.py", line 187, in _get_response
    response = self.process_exception_by_middleware(e, request)
  File "/Library/Frameworks/Python.framework/Versions/3.6/lib/python3.6/site-packages/django/core/handlers/base.py", line 185, in _get_response
    response = wrapped_callback(request, *callback_args, **callback_kwargs)
  File "/Library/Frameworks/Python.framework/Versions/3.6/lib/python3.6/site-packages/django/contrib/auth/decorators.py", line 23, in _wrapped_view
    return view_func(request, *args, **kwargs)
  File "/Users/zhuzhanhao/Testapi/Api/api/view_process.py", line 726, in show_progress_views
    return HttpResponse(num_progress, safe=False)
  File "/Library/Frameworks/Python.framework/Versions/3.6/lib/python3.6/site-packages/django/http/response.py", line 301, in __init__
    super(HttpResponse, self).__init__(*args, **kwargs)
TypeError: __init__() got an unexpected keyword argument 'safe'
[2019-12-07 18:24:29,815] [ERROR] [log_message] : "GET /show_progress/ HTTP/1.1" 500 15136
[2019-12-07 18:24:30,030] [ERROR] [handle_uncaught_exception] : Internal Server Error: /show_progress/
Traceback (most recent call last):
  File "/Library/Frameworks/Python.framework/Versions/3.6/lib/python3.6/site-packages/django/core/handlers/exception.py", line 41, in inner
    response = get_response(request)
  File "/Library/Frameworks/Python.framework/Versions/3.6/lib/python3.6/site-packages/django/core/handlers/base.py", line 187, in _get_response
    response = self.process_exception_by_middleware(e, request)
  File "/Library/Frameworks/Python.framework/Versions/3.6/lib/python3.6/site-packages/django/core/handlers/base.py", line 185, in _get_response
    response = wrapped_callback(request, *callback_args, **callback_kwargs)
  File "/Library/Frameworks/Python.framework/Versions/3.6/lib/python3.6/site-packages/django/contrib/auth/decorators.py", line 23, in _wrapped_view
    return view_func(request, *args, **kwargs)
  File "/Users/zhuzhanhao/Testapi/Api/api/view_process.py", line 726, in show_progress_views
    return HttpResponse(num_progress, safe=False)
  File "/Library/Frameworks/Python.framework/Versions/3.6/lib/python3.6/site-packages/django/http/response.py", line 301, in __init__
    super(HttpResponse, self).__init__(*args, **kwargs)
TypeError: __init__() got an unexpected keyword argument 'safe'
[2019-12-07 18:24:30,073] [ERROR] [log_message] : "GET /show_progress/ HTTP/1.1" 500 15136
[2019-12-07 20:50:27,556] [ERROR] [handle_uncaught_exception] : Internal Server Error: /show_progress/
Traceback (most recent call last):
  File "/Library/Frameworks/Python.framework/Versions/3.6/lib/python3.6/site-packages/django/contrib/sessions/backends/base.py", line 202, in _get_session
    return self._session_cache
AttributeError: 'SessionStore' object has no attribute '_session_cache'

During handling of the above exception, another exception occurred:

Traceback (most recent call last):
  File "/Library/Frameworks/Python.framework/Versions/3.6/lib/python3.6/site-packages/pymysql/connections.py", line 690, in _read_bytes
    data = self._rfile.read(num_bytes)
  File "/Library/Frameworks/Python.framework/Versions/3.6/lib/python3.6/socket.py", line 586, in readinto
    return self._sock.recv_into(b)
TimeoutError: [Errno 60] Operation timed out

During handling of the above exception, another exception occurred:

Traceback (most recent call last):
  File "/Library/Frameworks/Python.framework/Versions/3.6/lib/python3.6/site-packages/django/db/backends/base/base.py", line 213, in ensure_connection
    self.connect()
  File "/Library/Frameworks/Python.framework/Versions/3.6/lib/python3.6/site-packages/django/db/backends/base/base.py", line 189, in connect
    self.connection = self.get_new_connection(conn_params)
  File "/Library/Frameworks/Python.framework/Versions/3.6/lib/python3.6/site-packages/django/db/backends/mysql/base.py", line 274, in get_new_connection
    conn = Database.connect(**conn_params)
  File "/Library/Frameworks/Python.framework/Versions/3.6/lib/python3.6/site-packages/pymysql/__init__.py", line 94, in Connect
    return Connection(*args, **kwargs)
  File "/Library/Frameworks/Python.framework/Versions/3.6/lib/python3.6/site-packages/pymysql/connections.py", line 327, in __init__
    self.connect()
  File "/Library/Frameworks/Python.framework/Versions/3.6/lib/python3.6/site-packages/pymysql/connections.py", line 598, in connect
    self._request_authentication()
  File "/Library/Frameworks/Python.framework/Versions/3.6/lib/python3.6/site-packages/pymysql/connections.py", line 862, in _request_authentication
    auth_packet = self._process_auth(plugin_name, auth_packet)
  File "/Library/Frameworks/Python.framework/Versions/3.6/lib/python3.6/site-packages/pymysql/connections.py", line 933, in _process_auth
    pkt = self._read_packet()
  File "/Library/Frameworks/Python.framework/Versions/3.6/lib/python3.6/site-packages/pymysql/connections.py", line 656, in _read_packet
    packet_header = self._read_bytes(4)
  File "/Library/Frameworks/Python.framework/Versions/3.6/lib/python3.6/site-packages/pymysql/connections.py", line 698, in _read_bytes
    "Lost connection to MySQL server during query (%s)" % (e,))
pymysql.err.OperationalError: (2013, 'Lost connection to MySQL server during query ([Errno 60] Operation timed out)')

The above exception was the direct cause of the following exception:

Traceback (most recent call last):
  File "/Library/Frameworks/Python.framework/Versions/3.6/lib/python3.6/site-packages/django/core/handlers/exception.py", line 41, in inner
    response = get_response(request)
  File "/Library/Frameworks/Python.framework/Versions/3.6/lib/python3.6/site-packages/django/core/handlers/base.py", line 187, in _get_response
    response = self.process_exception_by_middleware(e, request)
  File "/Library/Frameworks/Python.framework/Versions/3.6/lib/python3.6/site-packages/django/core/handlers/base.py", line 185, in _get_response
    response = wrapped_callback(request, *callback_args, **callback_kwargs)
  File "/Library/Frameworks/Python.framework/Versions/3.6/lib/python3.6/site-packages/django/contrib/auth/decorators.py", line 22, in _wrapped_view
    if test_func(request.user):
  File "/Library/Frameworks/Python.framework/Versions/3.6/lib/python3.6/site-packages/django/contrib/auth/decorators.py", line 46, in <lambda>
    lambda u: u.is_authenticated,
  File "/Library/Frameworks/Python.framework/Versions/3.6/lib/python3.6/site-packages/django/utils/functional.py", line 238, in inner
    self._setup()
  File "/Library/Frameworks/Python.framework/Versions/3.6/lib/python3.6/site-packages/django/utils/functional.py", line 386, in _setup
    self._wrapped = self._setupfunc()
  File "/Library/Frameworks/Python.framework/Versions/3.6/lib/python3.6/site-packages/django/contrib/auth/middleware.py", line 24, in <lambda>
    request.user = SimpleLazyObject(lambda: get_user(request))
  File "/Library/Frameworks/Python.framework/Versions/3.6/lib/python3.6/site-packages/django/contrib/auth/middleware.py", line 12, in get_user
    request._cached_user = auth.get_user(request)
  File "/Library/Frameworks/Python.framework/Versions/3.6/lib/python3.6/site-packages/django/contrib/auth/__init__.py", line 210, in get_user
    user_id = _get_user_session_key(request)
  File "/Library/Frameworks/Python.framework/Versions/3.6/lib/python3.6/site-packages/django/contrib/auth/__init__.py", line 61, in _get_user_session_key
    return get_user_model()._meta.pk.to_python(request.session[SESSION_KEY])
  File "/Library/Frameworks/Python.framework/Versions/3.6/lib/python3.6/site-packages/django/contrib/sessions/backends/base.py", line 57, in __getitem__
    return self._session[key]
  File "/Library/Frameworks/Python.framework/Versions/3.6/lib/python3.6/site-packages/django/contrib/sessions/backends/base.py", line 207, in _get_session
    self._session_cache = self.load()
  File "/Library/Frameworks/Python.framework/Versions/3.6/lib/python3.6/site-packages/django/contrib/sessions/backends/db.py", line 35, in load
    expire_date__gt=timezone.now()
  File "/Library/Frameworks/Python.framework/Versions/3.6/lib/python3.6/site-packages/django/db/models/manager.py", line 85, in manager_method
    return getattr(self.get_queryset(), name)(*args, **kwargs)
  File "/Library/Frameworks/Python.framework/Versions/3.6/lib/python3.6/site-packages/django/db/models/query.py", line 374, in get
    num = len(clone)
  File "/Library/Frameworks/Python.framework/Versions/3.6/lib/python3.6/site-packages/django/db/models/query.py", line 232, in __len__
    self._fetch_all()
  File "/Library/Frameworks/Python.framework/Versions/3.6/lib/python3.6/site-packages/django/db/models/query.py", line 1118, in _fetch_all
    self._result_cache = list(self._iterable_class(self))
  File "/Library/Frameworks/Python.framework/Versions/3.6/lib/python3.6/site-packages/django/db/models/query.py", line 53, in __iter__
    results = compiler.execute_sql(chunked_fetch=self.chunked_fetch)
  File "/Library/Frameworks/Python.framework/Versions/3.6/lib/python3.6/site-packages/django/db/models/sql/compiler.py", line 876, in execute_sql
    sql, params = self.as_sql()
  File "/Library/Frameworks/Python.framework/Versions/3.6/lib/python3.6/site-packages/django/db/models/sql/compiler.py", line 441, in as_sql
    where, w_params = self.compile(self.where) if self.where is not None else ("", [])
  File "/Library/Frameworks/Python.framework/Versions/3.6/lib/python3.6/site-packages/django/db/models/sql/compiler.py", line 373, in compile
    sql, params = node.as_sql(self, self.connection)
  File "/Library/Frameworks/Python.framework/Versions/3.6/lib/python3.6/site-packages/django/db/models/sql/where.py", line 79, in as_sql
    sql, params = compiler.compile(child)
  File "/Library/Frameworks/Python.framework/Versions/3.6/lib/python3.6/site-packages/django/db/models/sql/compiler.py", line 373, in compile
    sql, params = node.as_sql(self, self.connection)
  File "/Library/Frameworks/Python.framework/Versions/3.6/lib/python3.6/site-packages/django/db/models/lookups.py", line 169, in as_sql
    lhs_sql, params = self.process_lhs(compiler, connection)
  File "/Library/Frameworks/Python.framework/Versions/3.6/lib/python3.6/site-packages/django/db/models/lookups.py", line 162, in process_lhs
    db_type = self.lhs.output_field.db_type(connection=connection)
  File "/Library/Frameworks/Python.framework/Versions/3.6/lib/python3.6/site-packages/django/db/models/fields/__init__.py", line 644, in db_type
    return connection.data_types[self.get_internal_type()] % data
  File "/Library/Frameworks/Python.framework/Versions/3.6/lib/python3.6/site-packages/django/utils/functional.py", line 35, in __get__
    res = instance.__dict__[self.name] = self.func(instance)
  File "/Library/Frameworks/Python.framework/Versions/3.6/lib/python3.6/site-packages/django/db/backends/mysql/base.py", line 174, in data_types
    if self.features.supports_microsecond_precision:
  File "/Library/Frameworks/Python.framework/Versions/3.6/lib/python3.6/site-packages/django/utils/functional.py", line 35, in __get__
    res = instance.__dict__[self.name] = self.func(instance)
  File "/Library/Frameworks/Python.framework/Versions/3.6/lib/python3.6/site-packages/django/db/backends/mysql/features.py", line 53, in supports_microsecond_precision
    return self.connection.mysql_version >= (5, 6, 4) and Database.version_info >= (1, 2, 5)
  File "/Library/Frameworks/Python.framework/Versions/3.6/lib/python3.6/site-packages/django/utils/functional.py", line 35, in __get__
    res = instance.__dict__[self.name] = self.func(instance)
  File "/Library/Frameworks/Python.framework/Versions/3.6/lib/python3.6/site-packages/django/db/backends/mysql/base.py", line 385, in mysql_version
    with self.temporary_connection() as cursor:
  File "/Library/Frameworks/Python.framework/Versions/3.6/lib/python3.6/contextlib.py", line 81, in __enter__
    return next(self.gen)
  File "/Library/Frameworks/Python.framework/Versions/3.6/lib/python3.6/site-packages/django/db/backends/base/base.py", line 591, in temporary_connection
    cursor = self.cursor()
  File "/Library/Frameworks/Python.framework/Versions/3.6/lib/python3.6/site-packages/django/db/backends/base/base.py", line 254, in cursor
    return self._cursor()
  File "/Library/Frameworks/Python.framework/Versions/3.6/lib/python3.6/site-packages/django/db/backends/base/base.py", line 229, in _cursor
    self.ensure_connection()
  File "/Library/Frameworks/Python.framework/Versions/3.6/lib/python3.6/site-packages/django/db/backends/base/base.py", line 213, in ensure_connection
    self.connect()
  File "/Library/Frameworks/Python.framework/Versions/3.6/lib/python3.6/site-packages/django/db/utils.py", line 94, in __exit__
    six.reraise(dj_exc_type, dj_exc_value, traceback)
  File "/Library/Frameworks/Python.framework/Versions/3.6/lib/python3.6/site-packages/django/utils/six.py", line 685, in reraise
    raise value.with_traceback(tb)
  File "/Library/Frameworks/Python.framework/Versions/3.6/lib/python3.6/site-packages/django/db/backends/base/base.py", line 213, in ensure_connection
    self.connect()
  File "/Library/Frameworks/Python.framework/Versions/3.6/lib/python3.6/site-packages/django/db/backends/base/base.py", line 189, in connect
    self.connection = self.get_new_connection(conn_params)
  File "/Library/Frameworks/Python.framework/Versions/3.6/lib/python3.6/site-packages/django/db/backends/mysql/base.py", line 274, in get_new_connection
    conn = Database.connect(**conn_params)
  File "/Library/Frameworks/Python.framework/Versions/3.6/lib/python3.6/site-packages/pymysql/__init__.py", line 94, in Connect
    return Connection(*args, **kwargs)
  File "/Library/Frameworks/Python.framework/Versions/3.6/lib/python3.6/site-packages/pymysql/connections.py", line 327, in __init__
    self.connect()
  File "/Library/Frameworks/Python.framework/Versions/3.6/lib/python3.6/site-packages/pymysql/connections.py", line 598, in connect
    self._request_authentication()
  File "/Library/Frameworks/Python.framework/Versions/3.6/lib/python3.6/site-packages/pymysql/connections.py", line 862, in _request_authentication
    auth_packet = self._process_auth(plugin_name, auth_packet)
  File "/Library/Frameworks/Python.framework/Versions/3.6/lib/python3.6/site-packages/pymysql/connections.py", line 933, in _process_auth
    pkt = self._read_packet()
  File "/Library/Frameworks/Python.framework/Versions/3.6/lib/python3.6/site-packages/pymysql/connections.py", line 656, in _read_packet
    packet_header = self._read_bytes(4)
  File "/Library/Frameworks/Python.framework/Versions/3.6/lib/python3.6/site-packages/pymysql/connections.py", line 698, in _read_bytes
    "Lost connection to MySQL server during query (%s)" % (e,))
django.db.utils.OperationalError: (2013, 'Lost connection to MySQL server during query ([Errno 60] Operation timed out)')
[2019-12-07 20:50:54,172] [ERROR] [handle_uncaught_exception] : Internal Server Error: /show_progress/
Traceback (most recent call last):
  File "/Library/Frameworks/Python.framework/Versions/3.6/lib/python3.6/site-packages/django/contrib/sessions/backends/base.py", line 202, in _get_session
    return self._session_cache
AttributeError: 'SessionStore' object has no attribute '_session_cache'

During handling of the above exception, another exception occurred:

Traceback (most recent call last):
  File "/Library/Frameworks/Python.framework/Versions/3.6/lib/python3.6/site-packages/pymysql/connections.py", line 690, in _read_bytes
    data = self._rfile.read(num_bytes)
  File "/Library/Frameworks/Python.framework/Versions/3.6/lib/python3.6/socket.py", line 586, in readinto
    return self._sock.recv_into(b)
TimeoutError: [Errno 60] Operation timed out

During handling of the above exception, another exception occurred:

Traceback (most recent call last):
  File "/Library/Frameworks/Python.framework/Versions/3.6/lib/python3.6/site-packages/django/db/backends/base/base.py", line 213, in ensure_connection
    self.connect()
  File "/Library/Frameworks/Python.framework/Versions/3.6/lib/python3.6/site-packages/django/db/backends/base/base.py", line 189, in connect
    self.connection = self.get_new_connection(conn_params)
  File "/Library/Frameworks/Python.framework/Versions/3.6/lib/python3.6/site-packages/django/db/backends/mysql/base.py", line 274, in get_new_connection
    conn = Database.connect(**conn_params)
  File "/Library/Frameworks/Python.framework/Versions/3.6/lib/python3.6/site-packages/pymysql/__init__.py", line 94, in Connect
    return Connection(*args, **kwargs)
  File "/Library/Frameworks/Python.framework/Versions/3.6/lib/python3.6/site-packages/pymysql/connections.py", line 327, in __init__
    self.connect()
  File "/Library/Frameworks/Python.framework/Versions/3.6/lib/python3.6/site-packages/pymysql/connections.py", line 611, in connect
    self.autocommit(self.autocommit_mode)
  File "/Library/Frameworks/Python.framework/Versions/3.6/lib/python3.6/site-packages/pymysql/connections.py", line 389, in autocommit
    self._send_autocommit_mode()
  File "/Library/Frameworks/Python.framework/Versions/3.6/lib/python3.6/site-packages/pymysql/connections.py", line 407, in _send_autocommit_mode
    self._read_ok_packet()
  File "/Library/Frameworks/Python.framework/Versions/3.6/lib/python3.6/site-packages/pymysql/connections.py", line 396, in _read_ok_packet
    pkt = self._read_packet()
  File "/Library/Frameworks/Python.framework/Versions/3.6/lib/python3.6/site-packages/pymysql/connections.py", line 656, in _read_packet
    packet_header = self._read_bytes(4)
  File "/Library/Frameworks/Python.framework/Versions/3.6/lib/python3.6/site-packages/pymysql/connections.py", line 698, in _read_bytes
    "Lost connection to MySQL server during query (%s)" % (e,))
pymysql.err.OperationalError: (2013, 'Lost connection to MySQL server during query ([Errno 60] Operation timed out)')

The above exception was the direct cause of the following exception:

Traceback (most recent call last):
  File "/Library/Frameworks/Python.framework/Versions/3.6/lib/python3.6/site-packages/django/core/handlers/exception.py", line 41, in inner
    response = get_response(request)
  File "/Library/Frameworks/Python.framework/Versions/3.6/lib/python3.6/site-packages/django/core/handlers/base.py", line 187, in _get_response
    response = self.process_exception_by_middleware(e, request)
  File "/Library/Frameworks/Python.framework/Versions/3.6/lib/python3.6/site-packages/django/core/handlers/base.py", line 185, in _get_response
    response = wrapped_callback(request, *callback_args, **callback_kwargs)
  File "/Library/Frameworks/Python.framework/Versions/3.6/lib/python3.6/site-packages/django/contrib/auth/decorators.py", line 22, in _wrapped_view
    if test_func(request.user):
  File "/Library/Frameworks/Python.framework/Versions/3.6/lib/python3.6/site-packages/django/contrib/auth/decorators.py", line 46, in <lambda>
    lambda u: u.is_authenticated,
  File "/Library/Frameworks/Python.framework/Versions/3.6/lib/python3.6/site-packages/django/utils/functional.py", line 238, in inner
    self._setup()
  File "/Library/Frameworks/Python.framework/Versions/3.6/lib/python3.6/site-packages/django/utils/functional.py", line 386, in _setup
    self._wrapped = self._setupfunc()
  File "/Library/Frameworks/Python.framework/Versions/3.6/lib/python3.6/site-packages/django/contrib/auth/middleware.py", line 24, in <lambda>
    request.user = SimpleLazyObject(lambda: get_user(request))
  File "/Library/Frameworks/Python.framework/Versions/3.6/lib/python3.6/site-packages/django/contrib/auth/middleware.py", line 12, in get_user
    request._cached_user = auth.get_user(request)
  File "/Library/Frameworks/Python.framework/Versions/3.6/lib/python3.6/site-packages/django/contrib/auth/__init__.py", line 210, in get_user
    user_id = _get_user_session_key(request)
  File "/Library/Frameworks/Python.framework/Versions/3.6/lib/python3.6/site-packages/django/contrib/auth/__init__.py", line 61, in _get_user_session_key
    return get_user_model()._meta.pk.to_python(request.session[SESSION_KEY])
  File "/Library/Frameworks/Python.framework/Versions/3.6/lib/python3.6/site-packages/django/contrib/sessions/backends/base.py", line 57, in __getitem__
    return self._session[key]
  File "/Library/Frameworks/Python.framework/Versions/3.6/lib/python3.6/site-packages/django/contrib/sessions/backends/base.py", line 207, in _get_session
    self._session_cache = self.load()
  File "/Library/Frameworks/Python.framework/Versions/3.6/lib/python3.6/site-packages/django/contrib/sessions/backends/db.py", line 35, in load
    expire_date__gt=timezone.now()
  File "/Library/Frameworks/Python.framework/Versions/3.6/lib/python3.6/site-packages/django/db/models/manager.py", line 85, in manager_method
    return getattr(self.get_queryset(), name)(*args, **kwargs)
  File "/Library/Frameworks/Python.framework/Versions/3.6/lib/python3.6/site-packages/django/db/models/query.py", line 374, in get
    num = len(clone)
  File "/Library/Frameworks/Python.framework/Versions/3.6/lib/python3.6/site-packages/django/db/models/query.py", line 232, in __len__
    self._fetch_all()
  File "/Library/Frameworks/Python.framework/Versions/3.6/lib/python3.6/site-packages/django/db/models/query.py", line 1118, in _fetch_all
    self._result_cache = list(self._iterable_class(self))
  File "/Library/Frameworks/Python.framework/Versions/3.6/lib/python3.6/site-packages/django/db/models/query.py", line 53, in __iter__
    results = compiler.execute_sql(chunked_fetch=self.chunked_fetch)
  File "/Library/Frameworks/Python.framework/Versions/3.6/lib/python3.6/site-packages/django/db/models/sql/compiler.py", line 876, in execute_sql
    sql, params = self.as_sql()
  File "/Library/Frameworks/Python.framework/Versions/3.6/lib/python3.6/site-packages/django/db/models/sql/compiler.py", line 441, in as_sql
    where, w_params = self.compile(self.where) if self.where is not None else ("", [])
  File "/Library/Frameworks/Python.framework/Versions/3.6/lib/python3.6/site-packages/django/db/models/sql/compiler.py", line 373, in compile
    sql, params = node.as_sql(self, self.connection)
  File "/Library/Frameworks/Python.framework/Versions/3.6/lib/python3.6/site-packages/django/db/models/sql/where.py", line 79, in as_sql
    sql, params = compiler.compile(child)
  File "/Library/Frameworks/Python.framework/Versions/3.6/lib/python3.6/site-packages/django/db/models/sql/compiler.py", line 373, in compile
    sql, params = node.as_sql(self, self.connection)
  File "/Library/Frameworks/Python.framework/Versions/3.6/lib/python3.6/site-packages/django/db/models/lookups.py", line 169, in as_sql
    lhs_sql, params = self.process_lhs(compiler, connection)
  File "/Library/Frameworks/Python.framework/Versions/3.6/lib/python3.6/site-packages/django/db/models/lookups.py", line 162, in process_lhs
    db_type = self.lhs.output_field.db_type(connection=connection)
  File "/Library/Frameworks/Python.framework/Versions/3.6/lib/python3.6/site-packages/django/db/models/fields/__init__.py", line 644, in db_type
    return connection.data_types[self.get_internal_type()] % data
  File "/Library/Frameworks/Python.framework/Versions/3.6/lib/python3.6/site-packages/django/utils/functional.py", line 35, in __get__
    res = instance.__dict__[self.name] = self.func(instance)
  File "/Library/Frameworks/Python.framework/Versions/3.6/lib/python3.6/site-packages/django/db/backends/mysql/base.py", line 174, in data_types
    if self.features.supports_microsecond_precision:
  File "/Library/Frameworks/Python.framework/Versions/3.6/lib/python3.6/site-packages/django/utils/functional.py", line 35, in __get__
    res = instance.__dict__[self.name] = self.func(instance)
  File "/Library/Frameworks/Python.framework/Versions/3.6/lib/python3.6/site-packages/django/db/backends/mysql/features.py", line 53, in supports_microsecond_precision
    return self.connection.mysql_version >= (5, 6, 4) and Database.version_info >= (1, 2, 5)
  File "/Library/Frameworks/Python.framework/Versions/3.6/lib/python3.6/site-packages/django/utils/functional.py", line 35, in __get__
    res = instance.__dict__[self.name] = self.func(instance)
  File "/Library/Frameworks/Python.framework/Versions/3.6/lib/python3.6/site-packages/django/db/backends/mysql/base.py", line 385, in mysql_version
    with self.temporary_connection() as cursor:
  File "/Library/Frameworks/Python.framework/Versions/3.6/lib/python3.6/contextlib.py", line 81, in __enter__
    return next(self.gen)
  File "/Library/Frameworks/Python.framework/Versions/3.6/lib/python3.6/site-packages/django/db/backends/base/base.py", line 591, in temporary_connection
    cursor = self.cursor()
  File "/Library/Frameworks/Python.framework/Versions/3.6/lib/python3.6/site-packages/django/db/backends/base/base.py", line 254, in cursor
    return self._cursor()
  File "/Library/Frameworks/Python.framework/Versions/3.6/lib/python3.6/site-packages/django/db/backends/base/base.py", line 229, in _cursor
    self.ensure_connection()
  File "/Library/Frameworks/Python.framework/Versions/3.6/lib/python3.6/site-packages/django/db/backends/base/base.py", line 213, in ensure_connection
    self.connect()
  File "/Library/Frameworks/Python.framework/Versions/3.6/lib/python3.6/site-packages/django/db/utils.py", line 94, in __exit__
    six.reraise(dj_exc_type, dj_exc_value, traceback)
  File "/Library/Frameworks/Python.framework/Versions/3.6/lib/python3.6/site-packages/django/utils/six.py", line 685, in reraise
    raise value.with_traceback(tb)
  File "/Library/Frameworks/Python.framework/Versions/3.6/lib/python3.6/site-packages/django/db/backends/base/base.py", line 213, in ensure_connection
    self.connect()
  File "/Library/Frameworks/Python.framework/Versions/3.6/lib/python3.6/site-packages/django/db/backends/base/base.py", line 189, in connect
    self.connection = self.get_new_connection(conn_params)
  File "/Library/Frameworks/Python.framework/Versions/3.6/lib/python3.6/site-packages/django/db/backends/mysql/base.py", line 274, in get_new_connection
    conn = Database.connect(**conn_params)
  File "/Library/Frameworks/Python.framework/Versions/3.6/lib/python3.6/site-packages/pymysql/__init__.py", line 94, in Connect
    return Connection(*args, **kwargs)
  File "/Library/Frameworks/Python.framework/Versions/3.6/lib/python3.6/site-packages/pymysql/connections.py", line 327, in __init__
    self.connect()
  File "/Library/Frameworks/Python.framework/Versions/3.6/lib/python3.6/site-packages/pymysql/connections.py", line 611, in connect
    self.autocommit(self.autocommit_mode)
  File "/Library/Frameworks/Python.framework/Versions/3.6/lib/python3.6/site-packages/pymysql/connections.py", line 389, in autocommit
    self._send_autocommit_mode()
  File "/Library/Frameworks/Python.framework/Versions/3.6/lib/python3.6/site-packages/pymysql/connections.py", line 407, in _send_autocommit_mode
    self._read_ok_packet()
  File "/Library/Frameworks/Python.framework/Versions/3.6/lib/python3.6/site-packages/pymysql/connections.py", line 396, in _read_ok_packet
    pkt = self._read_packet()
  File "/Library/Frameworks/Python.framework/Versions/3.6/lib/python3.6/site-packages/pymysql/connections.py", line 656, in _read_packet
    packet_header = self._read_bytes(4)
  File "/Library/Frameworks/Python.framework/Versions/3.6/lib/python3.6/site-packages/pymysql/connections.py", line 698, in _read_bytes
    "Lost connection to MySQL server during query (%s)" % (e,))
django.db.utils.OperationalError: (2013, 'Lost connection to MySQL server during query ([Errno 60] Operation timed out)')
[2019-12-07 20:51:11,363] [ERROR] [handle_uncaught_exception] : Internal Server Error: /show_progress/
Traceback (most recent call last):
  File "/Library/Frameworks/Python.framework/Versions/3.6/lib/python3.6/site-packages/django/contrib/sessions/backends/base.py", line 202, in _get_session
    return self._session_cache
AttributeError: 'SessionStore' object has no attribute '_session_cache'

During handling of the above exception, another exception occurred:

Traceback (most recent call last):
  File "/Library/Frameworks/Python.framework/Versions/3.6/lib/python3.6/site-packages/django/db/backends/base/base.py", line 213, in ensure_connection
    self.connect()
  File "/Library/Frameworks/Python.framework/Versions/3.6/lib/python3.6/site-packages/django/db/backends/base/base.py", line 189, in connect
    self.connection = self.get_new_connection(conn_params)
  File "/Library/Frameworks/Python.framework/Versions/3.6/lib/python3.6/site-packages/django/db/backends/mysql/base.py", line 274, in get_new_connection
    conn = Database.connect(**conn_params)
  File "/Library/Frameworks/Python.framework/Versions/3.6/lib/python3.6/site-packages/pymysql/__init__.py", line 94, in Connect
    return Connection(*args, **kwargs)
  File "/Library/Frameworks/Python.framework/Versions/3.6/lib/python3.6/site-packages/pymysql/connections.py", line 327, in __init__
    self.connect()
  File "/Library/Frameworks/Python.framework/Versions/3.6/lib/python3.6/site-packages/pymysql/connections.py", line 598, in connect
    self._request_authentication()
  File "/Library/Frameworks/Python.framework/Versions/3.6/lib/python3.6/site-packages/pymysql/connections.py", line 862, in _request_authentication
    auth_packet = self._process_auth(plugin_name, auth_packet)
  File "/Library/Frameworks/Python.framework/Versions/3.6/lib/python3.6/site-packages/pymysql/connections.py", line 933, in _process_auth
    pkt = self._read_packet()
  File "/Library/Frameworks/Python.framework/Versions/3.6/lib/python3.6/site-packages/pymysql/connections.py", line 656, in _read_packet
    packet_header = self._read_bytes(4)
  File "/Library/Frameworks/Python.framework/Versions/3.6/lib/python3.6/site-packages/pymysql/connections.py", line 702, in _read_bytes
    CR.CR_SERVER_LOST, "Lost connection to MySQL server during query")
pymysql.err.OperationalError: (2013, 'Lost connection to MySQL server during query')

The above exception was the direct cause of the following exception:

Traceback (most recent call last):
  File "/Library/Frameworks/Python.framework/Versions/3.6/lib/python3.6/site-packages/django/core/handlers/exception.py", line 41, in inner
    response = get_response(request)
  File "/Library/Frameworks/Python.framework/Versions/3.6/lib/python3.6/site-packages/django/core/handlers/base.py", line 187, in _get_response
    response = self.process_exception_by_middleware(e, request)
  File "/Library/Frameworks/Python.framework/Versions/3.6/lib/python3.6/site-packages/django/core/handlers/base.py", line 185, in _get_response
    response = wrapped_callback(request, *callback_args, **callback_kwargs)
  File "/Library/Frameworks/Python.framework/Versions/3.6/lib/python3.6/site-packages/django/contrib/auth/decorators.py", line 22, in _wrapped_view
    if test_func(request.user):
  File "/Library/Frameworks/Python.framework/Versions/3.6/lib/python3.6/site-packages/django/contrib/auth/decorators.py", line 46, in <lambda>
    lambda u: u.is_authenticated,
  File "/Library/Frameworks/Python.framework/Versions/3.6/lib/python3.6/site-packages/django/utils/functional.py", line 238, in inner
    self._setup()
  File "/Library/Frameworks/Python.framework/Versions/3.6/lib/python3.6/site-packages/django/utils/functional.py", line 386, in _setup
    self._wrapped = self._setupfunc()
  File "/Library/Frameworks/Python.framework/Versions/3.6/lib/python3.6/site-packages/django/contrib/auth/middleware.py", line 24, in <lambda>
    request.user = SimpleLazyObject(lambda: get_user(request))
  File "/Library/Frameworks/Python.framework/Versions/3.6/lib/python3.6/site-packages/django/contrib/auth/middleware.py", line 12, in get_user
    request._cached_user = auth.get_user(request)
  File "/Library/Frameworks/Python.framework/Versions/3.6/lib/python3.6/site-packages/django/contrib/auth/__init__.py", line 210, in get_user
    user_id = _get_user_session_key(request)
  File "/Library/Frameworks/Python.framework/Versions/3.6/lib/python3.6/site-packages/django/contrib/auth/__init__.py", line 61, in _get_user_session_key
    return get_user_model()._meta.pk.to_python(request.session[SESSION_KEY])
  File "/Library/Frameworks/Python.framework/Versions/3.6/lib/python3.6/site-packages/django/contrib/sessions/backends/base.py", line 57, in __getitem__
    return self._session[key]
  File "/Library/Frameworks/Python.framework/Versions/3.6/lib/python3.6/site-packages/django/contrib/sessions/backends/base.py", line 207, in _get_session
    self._session_cache = self.load()
  File "/Library/Frameworks/Python.framework/Versions/3.6/lib/python3.6/site-packages/django/contrib/sessions/backends/db.py", line 35, in load
    expire_date__gt=timezone.now()
  File "/Library/Frameworks/Python.framework/Versions/3.6/lib/python3.6/site-packages/django/db/models/manager.py", line 85, in manager_method
    return getattr(self.get_queryset(), name)(*args, **kwargs)
  File "/Library/Frameworks/Python.framework/Versions/3.6/lib/python3.6/site-packages/django/db/models/query.py", line 374, in get
    num = len(clone)
  File "/Library/Frameworks/Python.framework/Versions/3.6/lib/python3.6/site-packages/django/db/models/query.py", line 232, in __len__
    self._fetch_all()
  File "/Library/Frameworks/Python.framework/Versions/3.6/lib/python3.6/site-packages/django/db/models/query.py", line 1118, in _fetch_all
    self._result_cache = list(self._iterable_class(self))
  File "/Library/Frameworks/Python.framework/Versions/3.6/lib/python3.6/site-packages/django/db/models/query.py", line 53, in __iter__
    results = compiler.execute_sql(chunked_fetch=self.chunked_fetch)
  File "/Library/Frameworks/Python.framework/Versions/3.6/lib/python3.6/site-packages/django/db/models/sql/compiler.py", line 876, in execute_sql
    sql, params = self.as_sql()
  File "/Library/Frameworks/Python.framework/Versions/3.6/lib/python3.6/site-packages/django/db/models/sql/compiler.py", line 441, in as_sql
    where, w_params = self.compile(self.where) if self.where is not None else ("", [])
  File "/Library/Frameworks/Python.framework/Versions/3.6/lib/python3.6/site-packages/django/db/models/sql/compiler.py", line 373, in compile
    sql, params = node.as_sql(self, self.connection)
  File "/Library/Frameworks/Python.framework/Versions/3.6/lib/python3.6/site-packages/django/db/models/sql/where.py", line 79, in as_sql
    sql, params = compiler.compile(child)
  File "/Library/Frameworks/Python.framework/Versions/3.6/lib/python3.6/site-packages/django/db/models/sql/compiler.py", line 373, in compile
    sql, params = node.as_sql(self, self.connection)
  File "/Library/Frameworks/Python.framework/Versions/3.6/lib/python3.6/site-packages/django/db/models/lookups.py", line 169, in as_sql
    lhs_sql, params = self.process_lhs(compiler, connection)
  File "/Library/Frameworks/Python.framework/Versions/3.6/lib/python3.6/site-packages/django/db/models/lookups.py", line 162, in process_lhs
    db_type = self.lhs.output_field.db_type(connection=connection)
  File "/Library/Frameworks/Python.framework/Versions/3.6/lib/python3.6/site-packages/django/db/models/fields/__init__.py", line 644, in db_type
    return connection.data_types[self.get_internal_type()] % data
  File "/Library/Frameworks/Python.framework/Versions/3.6/lib/python3.6/site-packages/django/utils/functional.py", line 35, in __get__
    res = instance.__dict__[self.name] = self.func(instance)
  File "/Library/Frameworks/Python.framework/Versions/3.6/lib/python3.6/site-packages/django/db/backends/mysql/base.py", line 174, in data_types
    if self.features.supports_microsecond_precision:
  File "/Library/Frameworks/Python.framework/Versions/3.6/lib/python3.6/site-packages/django/utils/functional.py", line 35, in __get__
    res = instance.__dict__[self.name] = self.func(instance)
  File "/Library/Frameworks/Python.framework/Versions/3.6/lib/python3.6/site-packages/django/db/backends/mysql/features.py", line 53, in supports_microsecond_precision
    return self.connection.mysql_version >= (5, 6, 4) and Database.version_info >= (1, 2, 5)
  File "/Library/Frameworks/Python.framework/Versions/3.6/lib/python3.6/site-packages/django/utils/functional.py", line 35, in __get__
    res = instance.__dict__[self.name] = self.func(instance)
  File "/Library/Frameworks/Python.framework/Versions/3.6/lib/python3.6/site-packages/django/db/backends/mysql/base.py", line 385, in mysql_version
    with self.temporary_connection() as cursor:
  File "/Library/Frameworks/Python.framework/Versions/3.6/lib/python3.6/contextlib.py", line 81, in __enter__
    return next(self.gen)
  File "/Library/Frameworks/Python.framework/Versions/3.6/lib/python3.6/site-packages/django/db/backends/base/base.py", line 591, in temporary_connection
    cursor = self.cursor()
  File "/Library/Frameworks/Python.framework/Versions/3.6/lib/python3.6/site-packages/django/db/backends/base/base.py", line 254, in cursor
    return self._cursor()
  File "/Library/Frameworks/Python.framework/Versions/3.6/lib/python3.6/site-packages/django/db/backends/base/base.py", line 229, in _cursor
    self.ensure_connection()
  File "/Library/Frameworks/Python.framework/Versions/3.6/lib/python3.6/site-packages/django/db/backends/base/base.py", line 213, in ensure_connection
    self.connect()
  File "/Library/Frameworks/Python.framework/Versions/3.6/lib/python3.6/site-packages/django/db/utils.py", line 94, in __exit__
    six.reraise(dj_exc_type, dj_exc_value, traceback)
  File "/Library/Frameworks/Python.framework/Versions/3.6/lib/python3.6/site-packages/django/utils/six.py", line 685, in reraise
    raise value.with_traceback(tb)
  File "/Library/Frameworks/Python.framework/Versions/3.6/lib/python3.6/site-packages/django/db/backends/base/base.py", line 213, in ensure_connection
    self.connect()
  File "/Library/Frameworks/Python.framework/Versions/3.6/lib/python3.6/site-packages/django/db/backends/base/base.py", line 189, in connect
    self.connection = self.get_new_connection(conn_params)
  File "/Library/Frameworks/Python.framework/Versions/3.6/lib/python3.6/site-packages/django/db/backends/mysql/base.py", line 274, in get_new_connection
    conn = Database.connect(**conn_params)
  File "/Library/Frameworks/Python.framework/Versions/3.6/lib/python3.6/site-packages/pymysql/__init__.py", line 94, in Connect
    return Connection(*args, **kwargs)
  File "/Library/Frameworks/Python.framework/Versions/3.6/lib/python3.6/site-packages/pymysql/connections.py", line 327, in __init__
    self.connect()
  File "/Library/Frameworks/Python.framework/Versions/3.6/lib/python3.6/site-packages/pymysql/connections.py", line 598, in connect
    self._request_authentication()
  File "/Library/Frameworks/Python.framework/Versions/3.6/lib/python3.6/site-packages/pymysql/connections.py", line 862, in _request_authentication
    auth_packet = self._process_auth(plugin_name, auth_packet)
  File "/Library/Frameworks/Python.framework/Versions/3.6/lib/python3.6/site-packages/pymysql/connections.py", line 933, in _process_auth
    pkt = self._read_packet()
  File "/Library/Frameworks/Python.framework/Versions/3.6/lib/python3.6/site-packages/pymysql/connections.py", line 656, in _read_packet
    packet_header = self._read_bytes(4)
  File "/Library/Frameworks/Python.framework/Versions/3.6/lib/python3.6/site-packages/pymysql/connections.py", line 702, in _read_bytes
    CR.CR_SERVER_LOST, "Lost connection to MySQL server during query")
django.db.utils.OperationalError: (2013, 'Lost connection to MySQL server during query')
[2019-12-07 20:51:11,400] [ERROR] [handle_uncaught_exception] : Internal Server Error: /show_progress/
Traceback (most recent call last):
  File "/Library/Frameworks/Python.framework/Versions/3.6/lib/python3.6/site-packages/django/contrib/sessions/backends/base.py", line 202, in _get_session
    return self._session_cache
AttributeError: 'SessionStore' object has no attribute '_session_cache'

During handling of the above exception, another exception occurred:

Traceback (most recent call last):
  File "/Library/Frameworks/Python.framework/Versions/3.6/lib/python3.6/site-packages/django/db/backends/base/base.py", line 213, in ensure_connection
    self.connect()
  File "/Library/Frameworks/Python.framework/Versions/3.6/lib/python3.6/site-packages/django/db/backends/base/base.py", line 189, in connect
    self.connection = self.get_new_connection(conn_params)
  File "/Library/Frameworks/Python.framework/Versions/3.6/lib/python3.6/site-packages/django/db/backends/mysql/base.py", line 274, in get_new_connection
    conn = Database.connect(**conn_params)
  File "/Library/Frameworks/Python.framework/Versions/3.6/lib/python3.6/site-packages/pymysql/__init__.py", line 94, in Connect
    return Connection(*args, **kwargs)
  File "/Library/Frameworks/Python.framework/Versions/3.6/lib/python3.6/site-packages/pymysql/connections.py", line 327, in __init__
    self.connect()
  File "/Library/Frameworks/Python.framework/Versions/3.6/lib/python3.6/site-packages/pymysql/connections.py", line 598, in connect
    self._request_authentication()
  File "/Library/Frameworks/Python.framework/Versions/3.6/lib/python3.6/site-packages/pymysql/connections.py", line 852, in _request_authentication
    auth_packet = self._read_packet()
  File "/Library/Frameworks/Python.framework/Versions/3.6/lib/python3.6/site-packages/pymysql/connections.py", line 656, in _read_packet
    packet_header = self._read_bytes(4)
  File "/Library/Frameworks/Python.framework/Versions/3.6/lib/python3.6/site-packages/pymysql/connections.py", line 702, in _read_bytes
    CR.CR_SERVER_LOST, "Lost connection to MySQL server during query")
pymysql.err.OperationalError: (2013, 'Lost connection to MySQL server during query')

The above exception was the direct cause of the following exception:

Traceback (most recent call last):
  File "/Library/Frameworks/Python.framework/Versions/3.6/lib/python3.6/site-packages/django/core/handlers/exception.py", line 41, in inner
    response = get_response(request)
  File "/Library/Frameworks/Python.framework/Versions/3.6/lib/python3.6/site-packages/django/core/handlers/base.py", line 187, in _get_response
    response = self.process_exception_by_middleware(e, request)
  File "/Library/Frameworks/Python.framework/Versions/3.6/lib/python3.6/site-packages/django/core/handlers/base.py", line 185, in _get_response
    response = wrapped_callback(request, *callback_args, **callback_kwargs)
  File "/Library/Frameworks/Python.framework/Versions/3.6/lib/python3.6/site-packages/django/contrib/auth/decorators.py", line 22, in _wrapped_view
    if test_func(request.user):
  File "/Library/Frameworks/Python.framework/Versions/3.6/lib/python3.6/site-packages/django/contrib/auth/decorators.py", line 46, in <lambda>
    lambda u: u.is_authenticated,
  File "/Library/Frameworks/Python.framework/Versions/3.6/lib/python3.6/site-packages/django/utils/functional.py", line 238, in inner
    self._setup()
  File "/Library/Frameworks/Python.framework/Versions/3.6/lib/python3.6/site-packages/django/utils/functional.py", line 386, in _setup
    self._wrapped = self._setupfunc()
  File "/Library/Frameworks/Python.framework/Versions/3.6/lib/python3.6/site-packages/django/contrib/auth/middleware.py", line 24, in <lambda>
    request.user = SimpleLazyObject(lambda: get_user(request))
  File "/Library/Frameworks/Python.framework/Versions/3.6/lib/python3.6/site-packages/django/contrib/auth/middleware.py", line 12, in get_user
    request._cached_user = auth.get_user(request)
  File "/Library/Frameworks/Python.framework/Versions/3.6/lib/python3.6/site-packages/django/contrib/auth/__init__.py", line 210, in get_user
    user_id = _get_user_session_key(request)
  File "/Library/Frameworks/Python.framework/Versions/3.6/lib/python3.6/site-packages/django/contrib/auth/__init__.py", line 61, in _get_user_session_key
    return get_user_model()._meta.pk.to_python(request.session[SESSION_KEY])
  File "/Library/Frameworks/Python.framework/Versions/3.6/lib/python3.6/site-packages/django/contrib/sessions/backends/base.py", line 57, in __getitem__
    return self._session[key]
  File "/Library/Frameworks/Python.framework/Versions/3.6/lib/python3.6/site-packages/django/contrib/sessions/backends/base.py", line 207, in _get_session
    self._session_cache = self.load()
  File "/Library/Frameworks/Python.framework/Versions/3.6/lib/python3.6/site-packages/django/contrib/sessions/backends/db.py", line 35, in load
    expire_date__gt=timezone.now()
  File "/Library/Frameworks/Python.framework/Versions/3.6/lib/python3.6/site-packages/django/db/models/manager.py", line 85, in manager_method
    return getattr(self.get_queryset(), name)(*args, **kwargs)
  File "/Library/Frameworks/Python.framework/Versions/3.6/lib/python3.6/site-packages/django/db/models/query.py", line 374, in get
    num = len(clone)
  File "/Library/Frameworks/Python.framework/Versions/3.6/lib/python3.6/site-packages/django/db/models/query.py", line 232, in __len__
    self._fetch_all()
  File "/Library/Frameworks/Python.framework/Versions/3.6/lib/python3.6/site-packages/django/db/models/query.py", line 1118, in _fetch_all
    self._result_cache = list(self._iterable_class(self))
  File "/Library/Frameworks/Python.framework/Versions/3.6/lib/python3.6/site-packages/django/db/models/query.py", line 53, in __iter__
    results = compiler.execute_sql(chunked_fetch=self.chunked_fetch)
  File "/Library/Frameworks/Python.framework/Versions/3.6/lib/python3.6/site-packages/django/db/models/sql/compiler.py", line 876, in execute_sql
    sql, params = self.as_sql()
  File "/Library/Frameworks/Python.framework/Versions/3.6/lib/python3.6/site-packages/django/db/models/sql/compiler.py", line 441, in as_sql
    where, w_params = self.compile(self.where) if self.where is not None else ("", [])
  File "/Library/Frameworks/Python.framework/Versions/3.6/lib/python3.6/site-packages/django/db/models/sql/compiler.py", line 373, in compile
    sql, params = node.as_sql(self, self.connection)
  File "/Library/Frameworks/Python.framework/Versions/3.6/lib/python3.6/site-packages/django/db/models/sql/where.py", line 79, in as_sql
    sql, params = compiler.compile(child)
  File "/Library/Frameworks/Python.framework/Versions/3.6/lib/python3.6/site-packages/django/db/models/sql/compiler.py", line 373, in compile
    sql, params = node.as_sql(self, self.connection)
  File "/Library/Frameworks/Python.framework/Versions/3.6/lib/python3.6/site-packages/django/db/models/lookups.py", line 169, in as_sql
    lhs_sql, params = self.process_lhs(compiler, connection)
  File "/Library/Frameworks/Python.framework/Versions/3.6/lib/python3.6/site-packages/django/db/models/lookups.py", line 162, in process_lhs
    db_type = self.lhs.output_field.db_type(connection=connection)
  File "/Library/Frameworks/Python.framework/Versions/3.6/lib/python3.6/site-packages/django/db/models/fields/__init__.py", line 644, in db_type
    return connection.data_types[self.get_internal_type()] % data
  File "/Library/Frameworks/Python.framework/Versions/3.6/lib/python3.6/site-packages/django/utils/functional.py", line 35, in __get__
    res = instance.__dict__[self.name] = self.func(instance)
  File "/Library/Frameworks/Python.framework/Versions/3.6/lib/python3.6/site-packages/django/db/backends/mysql/base.py", line 174, in data_types
    if self.features.supports_microsecond_precision:
  File "/Library/Frameworks/Python.framework/Versions/3.6/lib/python3.6/site-packages/django/utils/functional.py", line 35, in __get__
    res = instance.__dict__[self.name] = self.func(instance)
  File "/Library/Frameworks/Python.framework/Versions/3.6/lib/python3.6/site-packages/django/db/backends/mysql/features.py", line 53, in supports_microsecond_precision
    return self.connection.mysql_version >= (5, 6, 4) and Database.version_info >= (1, 2, 5)
  File "/Library/Frameworks/Python.framework/Versions/3.6/lib/python3.6/site-packages/django/utils/functional.py", line 35, in __get__
    res = instance.__dict__[self.name] = self.func(instance)
  File "/Library/Frameworks/Python.framework/Versions/3.6/lib/python3.6/site-packages/django/db/backends/mysql/base.py", line 385, in mysql_version
    with self.temporary_connection() as cursor:
  File "/Library/Frameworks/Python.framework/Versions/3.6/lib/python3.6/contextlib.py", line 81, in __enter__
    return next(self.gen)
  File "/Library/Frameworks/Python.framework/Versions/3.6/lib/python3.6/site-packages/django/db/backends/base/base.py", line 591, in temporary_connection
    cursor = self.cursor()
  File "/Library/Frameworks/Python.framework/Versions/3.6/lib/python3.6/site-packages/django/db/backends/base/base.py", line 254, in cursor
    return self._cursor()
  File "/Library/Frameworks/Python.framework/Versions/3.6/lib/python3.6/site-packages/django/db/backends/base/base.py", line 229, in _cursor
    self.ensure_connection()
  File "/Library/Frameworks/Python.framework/Versions/3.6/lib/python3.6/site-packages/django/db/backends/base/base.py", line 213, in ensure_connection
    self.connect()
  File "/Library/Frameworks/Python.framework/Versions/3.6/lib/python3.6/site-packages/django/db/utils.py", line 94, in __exit__
    six.reraise(dj_exc_type, dj_exc_value, traceback)
  File "/Library/Frameworks/Python.framework/Versions/3.6/lib/python3.6/site-packages/django/utils/six.py", line 685, in reraise
    raise value.with_traceback(tb)
  File "/Library/Frameworks/Python.framework/Versions/3.6/lib/python3.6/site-packages/django/db/backends/base/base.py", line 213, in ensure_connection
    self.connect()
  File "/Library/Frameworks/Python.framework/Versions/3.6/lib/python3.6/site-packages/django/db/backends/base/base.py", line 189, in connect
    self.connection = self.get_new_connection(conn_params)
  File "/Library/Frameworks/Python.framework/Versions/3.6/lib/python3.6/site-packages/django/db/backends/mysql/base.py", line 274, in get_new_connection
    conn = Database.connect(**conn_params)
  File "/Library/Frameworks/Python.framework/Versions/3.6/lib/python3.6/site-packages/pymysql/__init__.py", line 94, in Connect
    return Connection(*args, **kwargs)
  File "/Library/Frameworks/Python.framework/Versions/3.6/lib/python3.6/site-packages/pymysql/connections.py", line 327, in __init__
    self.connect()
  File "/Library/Frameworks/Python.framework/Versions/3.6/lib/python3.6/site-packages/pymysql/connections.py", line 598, in connect
    self._request_authentication()
  File "/Library/Frameworks/Python.framework/Versions/3.6/lib/python3.6/site-packages/pymysql/connections.py", line 852, in _request_authentication
    auth_packet = self._read_packet()
  File "/Library/Frameworks/Python.framework/Versions/3.6/lib/python3.6/site-packages/pymysql/connections.py", line 656, in _read_packet
    packet_header = self._read_bytes(4)
  File "/Library/Frameworks/Python.framework/Versions/3.6/lib/python3.6/site-packages/pymysql/connections.py", line 702, in _read_bytes
    CR.CR_SERVER_LOST, "Lost connection to MySQL server during query")
django.db.utils.OperationalError: (2013, 'Lost connection to MySQL server during query')
[2019-12-07 20:51:13,133] [ERROR] [log_message] : "GET /show_progress/?_=1575722965396 HTTP/1.1" 500 26708
[2019-12-07 20:51:13,134] [ERROR] [log_message] : "GET /show_progress/?_=1575722965397 HTTP/1.1" 500 26433
[2019-12-07 20:51:14,081] [ERROR] [log_message] : "GET /show_progress/?_=1575722965398 HTTP/1.1" 500 25887
[2019-12-07 20:51:15,754] [ERROR] [log_message] : "GET /show_progress/?_=1575722965390 HTTP/1.1" 500 25487
[2019-12-07 23:21:10,343] [WARNING] [log_message] : "GET /static/images/login_bg.jpg HTTP/1.1" 404 1670
[2019-12-08 15:24:32,598] [WARNING] [log_message] : "GET /static/images/login_bg.jpg HTTP/1.1" 404 1670
[2019-12-08 17:32:45,134] [WARNING] [get_response] : Not Found: /zzhceshi/
[2019-12-08 17:32:45,137] [WARNING] [log_message] : "GET /zzhceshi/?_=1575797561957 HTTP/1.1" 404 11248
[2019-12-08 17:33:32,612] [WARNING] [get_response] : Not Found: /zzhceshi/
[2019-12-08 17:33:32,614] [WARNING] [log_message] : "GET /zzhceshi/?data=11111&_=1575797609407 HTTP/1.1" 404 11263
[2019-12-09 11:12:27,526] [WARNING] [get_response] : Not Found: /accounts/login/
[2019-12-09 11:12:27,528] [WARNING] [log_message] : "GET /accounts/login/?next=/web_index/ HTTP/1.1" 404 11267
[2019-12-09 11:12:27,962] [WARNING] [get_response] : Not Found: /favicon.ico
[2019-12-09 11:12:27,962] [WARNING] [log_message] : "GET /favicon.ico HTTP/1.1" 404 11238
[2019-12-09 11:12:36,790] [WARNING] [log_message] : "GET /static/images/login_bg.jpg HTTP/1.1" 404 1670
[2019-12-09 12:04:34,508] [ERROR] [handle_uncaught_exception] : Internal Server Error: /search/
Traceback (most recent call last):
  File "/Library/Frameworks/Python.framework/Versions/3.6/lib/python3.6/site-packages/django/core/handlers/exception.py", line 41, in inner
    response = get_response(request)
  File "/Library/Frameworks/Python.framework/Versions/3.6/lib/python3.6/site-packages/django/core/handlers/base.py", line 198, in _get_response
    "returned None instead." % (callback.__module__, view_name)
ValueError: The view Api.api.view_api.search_views didn't return an HttpResponse object. It returned None instead.
[2019-12-09 12:04:34,841] [ERROR] [log_message] : "POST /search/ HTTP/1.1" 500 14526
[2019-12-09 13:48:38,713] [ERROR] [handle_uncaught_exception] : Internal Server Error: /search/
Traceback (most recent call last):
  File "/Library/Frameworks/Python.framework/Versions/3.6/lib/python3.6/site-packages/django/core/handlers/exception.py", line 41, in inner
    response = get_response(request)
  File "/Library/Frameworks/Python.framework/Versions/3.6/lib/python3.6/site-packages/django/core/handlers/base.py", line 198, in _get_response
    "returned None instead." % (callback.__module__, view_name)
ValueError: The view Api.api.view_api.search_views didn't return an HttpResponse object. It returned None instead.
[2019-12-09 13:48:38,867] [ERROR] [log_message] : "POST /search/ HTTP/1.1" 500 14522
[2019-12-09 13:49:07,807] [ERROR] [handle_uncaught_exception] : Internal Server Error: /search/
Traceback (most recent call last):
  File "/Library/Frameworks/Python.framework/Versions/3.6/lib/python3.6/site-packages/django/core/handlers/exception.py", line 41, in inner
    response = get_response(request)
  File "/Library/Frameworks/Python.framework/Versions/3.6/lib/python3.6/site-packages/django/core/handlers/base.py", line 198, in _get_response
    "returned None instead." % (callback.__module__, view_name)
ValueError: The view Api.api.view_api.search_views didn't return an HttpResponse object. It returned None instead.
[2019-12-09 13:49:08,055] [ERROR] [log_message] : "POST /search/ HTTP/1.1" 500 14524
[2019-12-09 13:50:59,544] [ERROR] [handle_uncaught_exception] : Internal Server Error: /search/
Traceback (most recent call last):
  File "/Library/Frameworks/Python.framework/Versions/3.6/lib/python3.6/site-packages/django/core/handlers/exception.py", line 41, in inner
    response = get_response(request)
  File "/Library/Frameworks/Python.framework/Versions/3.6/lib/python3.6/site-packages/django/core/handlers/base.py", line 198, in _get_response
    "returned None instead." % (callback.__module__, view_name)
ValueError: The view Api.api.view_api.search_views didn't return an HttpResponse object. It returned None instead.
[2019-12-09 13:50:59,873] [ERROR] [log_message] : "POST /search/ HTTP/1.1" 500 14526
[2019-12-09 14:00:01,962] [ERROR] [handle_uncaught_exception] : Internal Server Error: /search/
Traceback (most recent call last):
  File "/Library/Frameworks/Python.framework/Versions/3.6/lib/python3.6/site-packages/django/core/handlers/exception.py", line 41, in inner
    response = get_response(request)
  File "/Library/Frameworks/Python.framework/Versions/3.6/lib/python3.6/site-packages/django/core/handlers/base.py", line 187, in _get_response
    response = self.process_exception_by_middleware(e, request)
  File "/Library/Frameworks/Python.framework/Versions/3.6/lib/python3.6/site-packages/django/core/handlers/base.py", line 185, in _get_response
    response = wrapped_callback(request, *callback_args, **callback_kwargs)
  File "/Users/zhuzhanhao/Testapi/Api/api/view_api.py", line 1098, in search_views
    pageInator = Paginator(L, pagesize)
  File "/Library/Frameworks/Python.framework/Versions/3.6/lib/python3.6/site-packages/django/core/paginator.py", line 32, in __init__
    self.per_page = int(per_page)
ValueError: invalid literal for int() with base 10: ''
[2019-12-09 14:00:02,067] [ERROR] [log_message] : "POST /search/ HTTP/1.1" 500 14923
[2019-12-09 14:04:01,555] [ERROR] [handle_uncaught_exception] : Internal Server Error: /search/
Traceback (most recent call last):
  File "/Library/Frameworks/Python.framework/Versions/3.6/lib/python3.6/site-packages/django/core/handlers/exception.py", line 41, in inner
    response = get_response(request)
  File "/Library/Frameworks/Python.framework/Versions/3.6/lib/python3.6/site-packages/django/core/handlers/base.py", line 187, in _get_response
    response = self.process_exception_by_middleware(e, request)
  File "/Library/Frameworks/Python.framework/Versions/3.6/lib/python3.6/site-packages/django/core/handlers/base.py", line 185, in _get_response
    response = wrapped_callback(request, *callback_args, **callback_kwargs)
  File "/Users/zhuzhanhao/Testapi/Api/api/view_api.py", line 1098, in search_views
    pageInator = Paginator(L, pagesize)
  File "/Library/Frameworks/Python.framework/Versions/3.6/lib/python3.6/site-packages/django/core/paginator.py", line 32, in __init__
    self.per_page = int(per_page)
ValueError: invalid literal for int() with base 10: ''
[2019-12-09 14:04:01,628] [ERROR] [log_message] : "POST /search/ HTTP/1.1" 500 14922
[2019-12-09 14:06:47,731] [ERROR] [handle_uncaught_exception] : Internal Server Error: /search/
Traceback (most recent call last):
  File "/Library/Frameworks/Python.framework/Versions/3.6/lib/python3.6/site-packages/django/core/handlers/exception.py", line 41, in inner
    response = get_response(request)
  File "/Library/Frameworks/Python.framework/Versions/3.6/lib/python3.6/site-packages/django/core/handlers/base.py", line 187, in _get_response
    response = self.process_exception_by_middleware(e, request)
  File "/Library/Frameworks/Python.framework/Versions/3.6/lib/python3.6/site-packages/django/core/handlers/base.py", line 185, in _get_response
    response = wrapped_callback(request, *callback_args, **callback_kwargs)
  File "/Users/zhuzhanhao/Testapi/Api/api/view_api.py", line 1098, in search_views
    pageInator = Paginator(L, pagesize)
  File "/Library/Frameworks/Python.framework/Versions/3.6/lib/python3.6/site-packages/django/core/paginator.py", line 32, in __init__
    self.per_page = int(per_page)
ValueError: invalid literal for int() with base 10: ''
[2019-12-09 14:06:47,811] [ERROR] [log_message] : "POST /search/ HTTP/1.1" 500 14923
[2019-12-09 14:08:52,951] [ERROR] [handle_uncaught_exception] : Internal Server Error: /search/
Traceback (most recent call last):
  File "/Library/Frameworks/Python.framework/Versions/3.6/lib/python3.6/site-packages/django/core/handlers/exception.py", line 41, in inner
    response = get_response(request)
  File "/Library/Frameworks/Python.framework/Versions/3.6/lib/python3.6/site-packages/django/core/handlers/base.py", line 187, in _get_response
    response = self.process_exception_by_middleware(e, request)
  File "/Library/Frameworks/Python.framework/Versions/3.6/lib/python3.6/site-packages/django/core/handlers/base.py", line 185, in _get_response
    response = wrapped_callback(request, *callback_args, **callback_kwargs)
  File "/Users/zhuzhanhao/Testapi/Api/api/view_api.py", line 1098, in search_views
    pageInator = Paginator(L, pagesize)
  File "/Library/Frameworks/Python.framework/Versions/3.6/lib/python3.6/site-packages/django/core/paginator.py", line 32, in __init__
    self.per_page = int(per_page)
ValueError: invalid literal for int() with base 10: ''
[2019-12-09 14:08:53,007] [ERROR] [log_message] : "POST /search/ HTTP/1.1" 500 14922
[2019-12-09 14:11:17,966] [ERROR] [handle_uncaught_exception] : Internal Server Error: /search/
Traceback (most recent call last):
  File "/Library/Frameworks/Python.framework/Versions/3.6/lib/python3.6/site-packages/django/core/handlers/exception.py", line 41, in inner
    response = get_response(request)
  File "/Library/Frameworks/Python.framework/Versions/3.6/lib/python3.6/site-packages/django/core/handlers/base.py", line 187, in _get_response
    response = self.process_exception_by_middleware(e, request)
  File "/Library/Frameworks/Python.framework/Versions/3.6/lib/python3.6/site-packages/django/core/handlers/base.py", line 185, in _get_response
    response = wrapped_callback(request, *callback_args, **callback_kwargs)
  File "/Users/zhuzhanhao/Testapi/Api/api/view_api.py", line 1098, in search_views
    pageInator = Paginator(L, pagesize)
  File "/Library/Frameworks/Python.framework/Versions/3.6/lib/python3.6/site-packages/django/core/paginator.py", line 32, in __init__
    self.per_page = int(per_page)
ValueError: invalid literal for int() with base 10: ''
[2019-12-09 14:11:18,112] [ERROR] [log_message] : "POST /search/ HTTP/1.1" 500 14922
[2019-12-09 14:13:15,068] [ERROR] [handle_uncaught_exception] : Internal Server Error: /search/
Traceback (most recent call last):
  File "/Library/Frameworks/Python.framework/Versions/3.6/lib/python3.6/site-packages/django/core/handlers/exception.py", line 41, in inner
    response = get_response(request)
  File "/Library/Frameworks/Python.framework/Versions/3.6/lib/python3.6/site-packages/django/core/handlers/base.py", line 187, in _get_response
    response = self.process_exception_by_middleware(e, request)
  File "/Library/Frameworks/Python.framework/Versions/3.6/lib/python3.6/site-packages/django/core/handlers/base.py", line 185, in _get_response
    response = wrapped_callback(request, *callback_args, **callback_kwargs)
  File "/Users/zhuzhanhao/Testapi/Api/api/view_api.py", line 1098, in search_views
    pageInator = Paginator(L, pagesize)
  File "/Library/Frameworks/Python.framework/Versions/3.6/lib/python3.6/site-packages/django/core/paginator.py", line 32, in __init__
    self.per_page = int(per_page)
ValueError: invalid literal for int() with base 10: ''
[2019-12-09 14:13:15,121] [ERROR] [log_message] : "POST /search/ HTTP/1.1" 500 14922
[2019-12-09 14:20:19,051] [ERROR] [handle_uncaught_exception] : Internal Server Error: /search/
Traceback (most recent call last):
  File "/Library/Frameworks/Python.framework/Versions/3.6/lib/python3.6/site-packages/django/core/handlers/exception.py", line 41, in inner
    response = get_response(request)
  File "/Library/Frameworks/Python.framework/Versions/3.6/lib/python3.6/site-packages/django/core/handlers/base.py", line 198, in _get_response
    "returned None instead." % (callback.__module__, view_name)
ValueError: The view Api.api.view_api.search_views didn't return an HttpResponse object. It returned None instead.
[2019-12-09 14:20:19,511] [ERROR] [log_message] : "GET /search/?page=1&limit=11 HTTP/1.1" 500 14510
[2019-12-09 14:38:59,318] [ERROR] [handle_uncaught_exception] : Internal Server Error: /search/
Traceback (most recent call last):
  File "/Library/Frameworks/Python.framework/Versions/3.6/lib/python3.6/site-packages/django/core/handlers/exception.py", line 41, in inner
    response = get_response(request)
  File "/Library/Frameworks/Python.framework/Versions/3.6/lib/python3.6/site-packages/django/core/handlers/base.py", line 187, in _get_response
    response = self.process_exception_by_middleware(e, request)
  File "/Library/Frameworks/Python.framework/Versions/3.6/lib/python3.6/site-packages/django/core/handlers/base.py", line 185, in _get_response
    response = wrapped_callback(request, *callback_args, **callback_kwargs)
  File "/Users/zhuzhanhao/Testapi/Api/api/view_api.py", line 1098, in search_views
    pageInator = Paginator(L, pagesize)
  File "/Library/Frameworks/Python.framework/Versions/3.6/lib/python3.6/site-packages/django/core/paginator.py", line 32, in __init__
    self.per_page = int(per_page)
ValueError: invalid literal for int() with base 10: ''
[2019-12-09 14:38:59,550] [ERROR] [log_message] : "POST /search/ HTTP/1.1" 500 14928
[2019-12-09 14:39:56,660] [ERROR] [log_message] : "POST /search/ HTTP/1.1" 500 59
[2019-12-09 14:42:48,636] [ERROR] [handle_uncaught_exception] : Internal Server Error: /search/
Traceback (most recent call last):
  File "/Library/Frameworks/Python.framework/Versions/3.6/lib/python3.6/site-packages/django/core/handlers/exception.py", line 41, in inner
    response = get_response(request)
  File "/Library/Frameworks/Python.framework/Versions/3.6/lib/python3.6/site-packages/django/core/handlers/base.py", line 198, in _get_response
    "returned None instead." % (callback.__module__, view_name)
ValueError: The view Api.api.view_api.search_views didn't return an HttpResponse object. It returned None instead.
[2019-12-09 14:42:48,872] [ERROR] [log_message] : "GET /search/?page=1&limit=10 HTTP/1.1" 500 14510
[2019-12-09 14:56:35,525] [WARNING] [get_response] : Not Found: /web_welcome/"{/"code/": 0, /"msg/": /"/", /"count/": 1, /"data/": [{/"caseid/": 386, /"belong/": /"//u6848//u5377//u7ba1//u7406//u63a5//u53e3/", /"processid/": /"/", /"identity/": /"tdradmin/", /"casename/": /"//u65b0//u5efa//u6848//u5377/", /"url/": /"http://amberdata.cn/tdrapi/volume/create_volume/", /"head/": /"//u8001//u674e/", /"method/": /"post/", /"params/": /"/", /"body/": /"/", /"result/": /"/", /"duration/": 1.0}]}"
[2019-12-09 14:56:35,527] [WARNING] [log_message] : "GET /web_welcome/%22%7B/%22code/%22:%200,%20/%22msg/%22:%20/%22/%22,%20/%22count/%22:%201,%20/%22data/%22:%20[%7B/%22caseid/%22:%20386,%20/%22belong/%22:%20/%22//u6848//u5377//u7ba1//u7406//u63a5//u53e3/%22,%20/%22processid/%22:%20/%22/%22,%20/%22identity/%22:%20/%22tdradmin/%22,%20/%22casename/%22:%20/%22//u65b0//u5efa//u6848//u5377/%22,%20/%22url/%22:%20/%22http://amberdata.cn/tdrapi/volume/create_volume/%22,%20/%22head/%22:%20/%22//u8001//u674e/%22,%20/%22method/%22:%20/%22post/%22,%20/%22params/%22:%20/%22/%22,%20/%22body/%22:%20/%22/%22,%20/%22result/%22:%20/%22/%22,%20/%22duration/%22:%201.0%7D]%7D%22?page=1&limit=10 HTTP/1.1" 404 13413
[2019-12-09 15:13:19,981] [ERROR] [handle_uncaught_exception] : Internal Server Error: /search
Traceback (most recent call last):
  File "/Library/Frameworks/Python.framework/Versions/3.6/lib/python3.6/site-packages/django/core/handlers/exception.py", line 41, in inner
    response = get_response(request)
  File "/Library/Frameworks/Python.framework/Versions/3.6/lib/python3.6/site-packages/django/core/handlers/base.py", line 198, in _get_response
    "returned None instead." % (callback.__module__, view_name)
ValueError: The view Api.api.view_api.search_views didn't return an HttpResponse object. It returned None instead.
[2019-12-09 15:13:20,270] [ERROR] [log_message] : "GET /search?key=%E6%96%B0%E5%BB%BA%E6%A1%88%E5%8D%B7&page=1&limit=10 HTTP/1.1" 500 14610
[2019-12-09 15:14:10,894] [ERROR] [handle_uncaught_exception] : Internal Server Error: /search
Traceback (most recent call last):
  File "/Library/Frameworks/Python.framework/Versions/3.6/lib/python3.6/site-packages/django/core/handlers/exception.py", line 41, in inner
    response = get_response(request)
  File "/Library/Frameworks/Python.framework/Versions/3.6/lib/python3.6/site-packages/django/core/handlers/base.py", line 198, in _get_response
    "returned None instead." % (callback.__module__, view_name)
ValueError: The view Api.api.view_api.search_views didn't return an HttpResponse object. It returned None instead.
[2019-12-09 15:14:11,245] [ERROR] [log_message] : "GET /search?key=%E6%96%B0%E5%BB%BA%E6%A1%88%E5%8D%B7&page=1&limit=10 HTTP/1.1" 500 14609
[2019-12-09 15:15:43,160] [ERROR] [handle_uncaught_exception] : Internal Server Error: /search
Traceback (most recent call last):
  File "/Library/Frameworks/Python.framework/Versions/3.6/lib/python3.6/site-packages/django/core/handlers/exception.py", line 41, in inner
    response = get_response(request)
  File "/Library/Frameworks/Python.framework/Versions/3.6/lib/python3.6/site-packages/django/core/handlers/base.py", line 198, in _get_response
    "returned None instead." % (callback.__module__, view_name)
ValueError: The view Api.api.view_api.search_views didn't return an HttpResponse object. It returned None instead.
[2019-12-09 15:15:43,314] [ERROR] [log_message] : "GET /search?key=11111111&page=1&limit=10 HTTP/1.1" 500 14551
[2019-12-09 15:16:20,546] [ERROR] [handle_uncaught_exception] : Internal Server Error: /search
Traceback (most recent call last):
  File "/Library/Frameworks/Python.framework/Versions/3.6/lib/python3.6/site-packages/django/core/handlers/exception.py", line 41, in inner
    response = get_response(request)
  File "/Library/Frameworks/Python.framework/Versions/3.6/lib/python3.6/site-packages/django/core/handlers/base.py", line 198, in _get_response
    "returned None instead." % (callback.__module__, view_name)
ValueError: The view Api.api.view_api.search_views didn't return an HttpResponse object. It returned None instead.
[2019-12-09 15:16:20,837] [ERROR] [log_message] : "GET /search?key=%E6%96%B0%E5%BB%BA&page=1&limit=10 HTTP/1.1" 500 14568
[2019-12-09 15:18:19,743] [ERROR] [handle_uncaught_exception] : Internal Server Error: /search
Traceback (most recent call last):
  File "/Library/Frameworks/Python.framework/Versions/3.6/lib/python3.6/site-packages/django/core/handlers/exception.py", line 41, in inner
    response = get_response(request)
  File "/Library/Frameworks/Python.framework/Versions/3.6/lib/python3.6/site-packages/django/core/handlers/base.py", line 198, in _get_response
    "returned None instead." % (callback.__module__, view_name)
ValueError: The view Api.api.view_api.search_views didn't return an HttpResponse object. It returned None instead.
[2019-12-09 15:18:19,993] [ERROR] [log_message] : "GET /search?key=aaaa&page=1&limit=10 HTTP/1.1" 500 14539
[2019-12-09 15:19:20,703] [ERROR] [handle_uncaught_exception] : Internal Server Error: /search
Traceback (most recent call last):
  File "/Library/Frameworks/Python.framework/Versions/3.6/lib/python3.6/site-packages/django/core/handlers/exception.py", line 41, in inner
    response = get_response(request)
  File "/Library/Frameworks/Python.framework/Versions/3.6/lib/python3.6/site-packages/django/core/handlers/base.py", line 198, in _get_response
    "returned None instead." % (callback.__module__, view_name)
ValueError: The view Api.api.view_api.search_views didn't return an HttpResponse object. It returned None instead.
[2019-12-09 15:19:20,856] [ERROR] [log_message] : "GET /search?key=782458422772823&page=1&limit=10 HTTP/1.1" 500 14571
[2019-12-09 15:19:47,464] [ERROR] [handle_uncaught_exception] : Internal Server Error: /search
Traceback (most recent call last):
  File "/Library/Frameworks/Python.framework/Versions/3.6/lib/python3.6/site-packages/django/core/handlers/exception.py", line 41, in inner
    response = get_response(request)
  File "/Library/Frameworks/Python.framework/Versions/3.6/lib/python3.6/site-packages/django/core/handlers/base.py", line 198, in _get_response
    "returned None instead." % (callback.__module__, view_name)
ValueError: The view Api.api.view_api.search_views didn't return an HttpResponse object. It returned None instead.
[2019-12-09 15:19:47,640] [ERROR] [log_message] : "GET /search?key=11111&page=1&limit=10 HTTP/1.1" 500 14541
[2019-12-09 16:01:28,195] [ERROR] [handle_uncaught_exception] : Internal Server Error: /search
Traceback (most recent call last):
  File "/Library/Frameworks/Python.framework/Versions/3.6/lib/python3.6/site-packages/django/core/handlers/exception.py", line 41, in inner
    response = get_response(request)
  File "/Library/Frameworks/Python.framework/Versions/3.6/lib/python3.6/site-packages/django/core/handlers/base.py", line 187, in _get_response
    response = self.process_exception_by_middleware(e, request)
  File "/Library/Frameworks/Python.framework/Versions/3.6/lib/python3.6/site-packages/django/core/handlers/base.py", line 185, in _get_response
    response = wrapped_callback(request, *callback_args, **callback_kwargs)
  File "/Users/zhuzhanhao/Testapi/Api/api/view_api.py", line 1098, in search_views
    pageInator = Paginator(L, pagesize)
  File "/Library/Frameworks/Python.framework/Versions/3.6/lib/python3.6/site-packages/django/core/paginator.py", line 32, in __init__
    self.per_page = int(per_page)
ValueError: invalid literal for int() with base 10: ''
[2019-12-09 16:01:28,369] [ERROR] [log_message] : "POST /search?key=%E8%80%81%E6%9D%8E HTTP/1.1" 500 14999
[2019-12-09 17:44:56,666] [ERROR] [handle_uncaught_exception] : Internal Server Error: /search
Traceback (most recent call last):
  File "/Library/Frameworks/Python.framework/Versions/3.6/lib/python3.6/site-packages/django/core/handlers/exception.py", line 41, in inner
    response = get_response(request)
  File "/Library/Frameworks/Python.framework/Versions/3.6/lib/python3.6/site-packages/django/core/handlers/base.py", line 198, in _get_response
    "returned None instead." % (callback.__module__, view_name)
ValueError: The view Api.api.view_api.search_views didn't return an HttpResponse object. It returned None instead.
[2019-12-09 17:44:56,886] [ERROR] [log_message] : "GET /search?key=&page=1&limit=10 HTTP/1.1" 500 14525
[2019-12-09 17:45:04,972] [ERROR] [handle_uncaught_exception] : Internal Server Error: /search
Traceback (most recent call last):
  File "/Library/Frameworks/Python.framework/Versions/3.6/lib/python3.6/site-packages/django/core/handlers/exception.py", line 41, in inner
    response = get_response(request)
  File "/Library/Frameworks/Python.framework/Versions/3.6/lib/python3.6/site-packages/django/core/handlers/base.py", line 198, in _get_response
    "returned None instead." % (callback.__module__, view_name)
ValueError: The view Api.api.view_api.search_views didn't return an HttpResponse object. It returned None instead.
[2019-12-09 17:45:05,134] [ERROR] [log_message] : "GET /search?key=&page=1&limit=10 HTTP/1.1" 500 14525
[2019-12-09 18:35:56,823] [WARNING] [get_response] : Not Found: /web_info/.static.images.json
[2019-12-09 18:35:56,828] [WARNING] [log_message] : "GET /web_info/.static.images.json HTTP/1.1" 404 11444
[2019-12-09 18:36:33,549] [WARNING] [get_response] : Not Found: /web_info/.static.images.json
[2019-12-09 18:36:33,550] [WARNING] [log_message] : "GET /web_info/.static.images.json HTTP/1.1" 404 11444
[2019-12-09 18:36:45,205] [WARNING] [get_response] : Not Found: /web_info/.static.images.json
[2019-12-09 18:36:45,207] [WARNING] [log_message] : "GET /web_info/.static.images.json HTTP/1.1" 404 11444
[2019-12-09 18:36:53,113] [WARNING] [get_response] : Not Found: /web_info/.static.images.json
[2019-12-09 18:36:53,114] [WARNING] [log_message] : "GET /web_info/.static.images.json HTTP/1.1" 404 11444
[2019-12-09 18:37:40,198] [WARNING] [get_response] : Not Found: /web_info/.static.images.json
[2019-12-09 18:37:40,199] [WARNING] [log_message] : "GET /web_info/.static.images.json HTTP/1.1" 404 11444
