[2019-12-03 18:07:56,222] [WARNING] [processlist_view] : 朱占豪测试日志级别
[2019-12-03 18:19:15,589] [WARNING] [get_response] : Not Found: /accounts/login/
[2019-12-03 18:19:15,590] [WARNING] [log_message] : "GET /accounts/login/?next=/web_index/ HTTP/1.1" 404 11267
[2019-12-03 18:19:15,679] [WARNING] [get_response] : Not Found: /favicon.ico
[2019-12-03 18:19:15,680] [WARNING] [log_message] : "GET /favicon.ico HTTP/1.1" 404 11238
[2019-12-03 18:21:46,099] [WARNING] [processlist_view] : 朱占豪测试日志级别
[2019-12-03 18:21:48,882] [WARNING] [processlist_view] : 朱占豪测试日志级别
[2019-12-03 19:48:31,758] [WARNING] [processlist_view] : 朱占豪测试日志级别
[2019-12-03 19:48:47,067] [WARNING] [processlist_view] : 朱占豪测试日志级别
[2019-12-03 19:52:34,023] [WARNING] [processlist_view] : 朱占豪测试日志级别
[2019-12-03 19:52:36,204] [WARNING] [processlist_view] : 朱占豪测试日志级别
[2019-12-03 19:52:43,403] [WARNING] [processlist_view] : 朱占豪测试日志级别
[2019-12-03 23:20:57,067] [WARNING] [processlist_view] : 朱占豪测试日志级别
[2019-12-04 11:15:42,462] [ERROR] [handle_uncaught_exception] : Internal Server Error: /processlist/
Traceback (most recent call last):
  File "/Library/Frameworks/Python.framework/Versions/3.6/lib/python3.6/site-packages/django/core/handlers/exception.py", line 41, in inner
    response = get_response(request)
  File "/Library/Frameworks/Python.framework/Versions/3.6/lib/python3.6/site-packages/django/core/handlers/base.py", line 187, in _get_response
    response = self.process_exception_by_middleware(e, request)
  File "/Library/Frameworks/Python.framework/Versions/3.6/lib/python3.6/site-packages/django/core/handlers/base.py", line 185, in _get_response
    response = wrapped_callback(request, *callback_args, **callback_kwargs)
  File "/Library/Frameworks/Python.framework/Versions/3.6/lib/python3.6/site-packages/django/contrib/auth/decorators.py", line 23, in _wrapped_view
    return view_func(request, *args, **kwargs)
  File "/Users/zhuzhanhao/Testapi/Api/view_process.py", line 291, in processlist_view
    for weblist in apilists:
UnboundLocalError: local variable 'apilists' referenced before assignment
[2019-12-04 11:15:42,808] [ERROR] [log_message] : "GET /processlist/?page=1&limit=30&belong=&system=erms&filterSos=%5B%7B%22prefix%22%3A%22and%22%2C%22field%22%3A%22casename%22%2C%22mode%22%3A%22condition%22%2C%22type%22%3A%22eq%22%2C%22value%22%3A%22%E6%96%B0%E5%BB%BA%22%2C%22id%22%3A1%7D%5D HTTP/1.1" 500 15560
[2019-12-04 11:34:52,436] [ERROR] [handle_uncaught_exception] : Internal Server Error: /processlist/
Traceback (most recent call last):
  File "/Library/Frameworks/Python.framework/Versions/3.6/lib/python3.6/site-packages/django/core/handlers/exception.py", line 41, in inner
    response = get_response(request)
  File "/Library/Frameworks/Python.framework/Versions/3.6/lib/python3.6/site-packages/django/core/handlers/base.py", line 187, in _get_response
    response = self.process_exception_by_middleware(e, request)
  File "/Library/Frameworks/Python.framework/Versions/3.6/lib/python3.6/site-packages/django/core/handlers/base.py", line 185, in _get_response
    response = wrapped_callback(request, *callback_args, **callback_kwargs)
  File "/Library/Frameworks/Python.framework/Versions/3.6/lib/python3.6/site-packages/django/contrib/auth/decorators.py", line 23, in _wrapped_view
    return view_func(request, *args, **kwargs)
  File "/Users/zhuzhanhao/Testapi/Api/view_process.py", line 117, in processlist_view
    for i in json.loads(filterSos):
  File "/Library/Frameworks/Python.framework/Versions/3.6/lib/python3.6/json/__init__.py", line 354, in loads
    return _default_decoder.decode(s)
  File "/Library/Frameworks/Python.framework/Versions/3.6/lib/python3.6/json/decoder.py", line 339, in decode
    obj, end = self.raw_decode(s, idx=_w(s, 0).end())
  File "/Library/Frameworks/Python.framework/Versions/3.6/lib/python3.6/json/decoder.py", line 357, in raw_decode
    raise JSONDecodeError("Expecting value", s, err.value) from None
json.decoder.JSONDecodeError: Expecting value: line 1 column 1 (char 0)
[2019-12-04 11:34:52,569] [ERROR] [log_message] : "GET /processlist/?page=1&limit=30&belong=&system=erms&key%5Bcasename%5D=%E9%94%99%E8%AF%AF%E6%8E%A5%E5%8F%A3%E6%9F%A5%E8%AF%A2 HTTP/1.1" 500 15984
[2019-12-04 11:36:23,666] [ERROR] [handle_uncaught_exception] : Internal Server Error: /processlist/
Traceback (most recent call last):
  File "/Library/Frameworks/Python.framework/Versions/3.6/lib/python3.6/site-packages/django/core/handlers/exception.py", line 41, in inner
    response = get_response(request)
  File "/Library/Frameworks/Python.framework/Versions/3.6/lib/python3.6/site-packages/django/core/handlers/base.py", line 187, in _get_response
    response = self.process_exception_by_middleware(e, request)
  File "/Library/Frameworks/Python.framework/Versions/3.6/lib/python3.6/site-packages/django/core/handlers/base.py", line 185, in _get_response
    response = wrapped_callback(request, *callback_args, **callback_kwargs)
  File "/Library/Frameworks/Python.framework/Versions/3.6/lib/python3.6/site-packages/django/contrib/auth/decorators.py", line 23, in _wrapped_view
    return view_func(request, *args, **kwargs)
  File "/Users/zhuzhanhao/Testapi/Api/view_process.py", line 117, in processlist_view
    for i in json.loads(filterSos):
  File "/Library/Frameworks/Python.framework/Versions/3.6/lib/python3.6/json/__init__.py", line 354, in loads
    return _default_decoder.decode(s)
  File "/Library/Frameworks/Python.framework/Versions/3.6/lib/python3.6/json/decoder.py", line 339, in decode
    obj, end = self.raw_decode(s, idx=_w(s, 0).end())
  File "/Library/Frameworks/Python.framework/Versions/3.6/lib/python3.6/json/decoder.py", line 357, in raw_decode
    raise JSONDecodeError("Expecting value", s, err.value) from None
json.decoder.JSONDecodeError: Expecting value: line 1 column 1 (char 0)
[2019-12-04 11:36:23,690] [ERROR] [log_message] : "GET /processlist/?page=1&limit=30&belong=&system=erms&key%5Bcasename%5D=%E9%94%99%E8%AF%AF%E6%8E%A5%E5%8F%A3%E6%9F%A5%E8%AF%A2 HTTP/1.1" 500 15984
[2019-12-04 11:36:56,429] [ERROR] [handle_uncaught_exception] : Internal Server Error: /processlist/
Traceback (most recent call last):
  File "/Library/Frameworks/Python.framework/Versions/3.6/lib/python3.6/site-packages/django/core/handlers/exception.py", line 41, in inner
    response = get_response(request)
  File "/Library/Frameworks/Python.framework/Versions/3.6/lib/python3.6/site-packages/django/core/handlers/base.py", line 187, in _get_response
    response = self.process_exception_by_middleware(e, request)
  File "/Library/Frameworks/Python.framework/Versions/3.6/lib/python3.6/site-packages/django/core/handlers/base.py", line 185, in _get_response
    response = wrapped_callback(request, *callback_args, **callback_kwargs)
  File "/Library/Frameworks/Python.framework/Versions/3.6/lib/python3.6/site-packages/django/contrib/auth/decorators.py", line 23, in _wrapped_view
    return view_func(request, *args, **kwargs)
  File "/Users/zhuzhanhao/Testapi/Api/view_process.py", line 117, in processlist_view
    for i in json.loads(filterSos):
  File "/Library/Frameworks/Python.framework/Versions/3.6/lib/python3.6/json/__init__.py", line 354, in loads
    return _default_decoder.decode(s)
  File "/Library/Frameworks/Python.framework/Versions/3.6/lib/python3.6/json/decoder.py", line 339, in decode
    obj, end = self.raw_decode(s, idx=_w(s, 0).end())
  File "/Library/Frameworks/Python.framework/Versions/3.6/lib/python3.6/json/decoder.py", line 357, in raw_decode
    raise JSONDecodeError("Expecting value", s, err.value) from None
json.decoder.JSONDecodeError: Expecting value: line 1 column 1 (char 0)
[2019-12-04 11:36:56,457] [ERROR] [log_message] : "GET /processlist/?page=1&limit=30&belong=&system=erms&key%5Bcasename%5D=A HTTP/1.1" 500 15861
[2019-12-04 11:38:32,017] [ERROR] [handle_uncaught_exception] : Internal Server Error: /processlist/
Traceback (most recent call last):
  File "/Library/Frameworks/Python.framework/Versions/3.6/lib/python3.6/site-packages/django/core/handlers/exception.py", line 41, in inner
    response = get_response(request)
  File "/Library/Frameworks/Python.framework/Versions/3.6/lib/python3.6/site-packages/django/core/handlers/base.py", line 187, in _get_response
    response = self.process_exception_by_middleware(e, request)
  File "/Library/Frameworks/Python.framework/Versions/3.6/lib/python3.6/site-packages/django/core/handlers/base.py", line 185, in _get_response
    response = wrapped_callback(request, *callback_args, **callback_kwargs)
  File "/Library/Frameworks/Python.framework/Versions/3.6/lib/python3.6/site-packages/django/contrib/auth/decorators.py", line 23, in _wrapped_view
    return view_func(request, *args, **kwargs)
  File "/Users/zhuzhanhao/Testapi/Api/view_process.py", line 117, in processlist_view
    for i in json.loads(filterSos):
  File "/Library/Frameworks/Python.framework/Versions/3.6/lib/python3.6/json/__init__.py", line 354, in loads
    return _default_decoder.decode(s)
  File "/Library/Frameworks/Python.framework/Versions/3.6/lib/python3.6/json/decoder.py", line 339, in decode
    obj, end = self.raw_decode(s, idx=_w(s, 0).end())
  File "/Library/Frameworks/Python.framework/Versions/3.6/lib/python3.6/json/decoder.py", line 357, in raw_decode
    raise JSONDecodeError("Expecting value", s, err.value) from None
json.decoder.JSONDecodeError: Expecting value: line 1 column 1 (char 0)
[2019-12-04 11:38:32,160] [ERROR] [log_message] : "GET /processlist/?page=1&limit=30&belong=&system=erms&key%5Bcasename%5D=%E9%94%99%E8%AF%AF%E6%8E%A5%E5%8F%A3%E6%9F%A5%E8%AF%A2 HTTP/1.1" 500 15984
[2019-12-06 22:34:34,349] [ERROR] [handle_uncaught_exception] : Internal Server Error: /web_index/
Traceback (most recent call last):
  File "/Library/Frameworks/Python.framework/Versions/3.6/lib/python3.6/site-packages/django/core/handlers/exception.py", line 41, in inner
    response = get_response(request)
  File "/Library/Frameworks/Python.framework/Versions/3.6/lib/python3.6/site-packages/django/core/handlers/base.py", line 187, in _get_response
    response = self.process_exception_by_middleware(e, request)
  File "/Library/Frameworks/Python.framework/Versions/3.6/lib/python3.6/site-packages/django/core/handlers/base.py", line 185, in _get_response
    response = wrapped_callback(request, *callback_args, **callback_kwargs)
  File "/Library/Frameworks/Python.framework/Versions/3.6/lib/python3.6/site-packages/django/contrib/auth/decorators.py", line 23, in _wrapped_view
    return view_func(request, *args, **kwargs)
  File "/Users/zhuzhanhao/Testapi/Api/views.py", line 69, in web_index_views
    return render(request, 'static/index.html')
  File "/Library/Frameworks/Python.framework/Versions/3.6/lib/python3.6/site-packages/django/shortcuts.py", line 30, in render
    content = loader.render_to_string(template_name, context, request, using=using)
  File "/Library/Frameworks/Python.framework/Versions/3.6/lib/python3.6/site-packages/django/template/loader.py", line 67, in render_to_string
    template = get_template(template_name, using=using)
  File "/Library/Frameworks/Python.framework/Versions/3.6/lib/python3.6/site-packages/django/template/loader.py", line 25, in get_template
    raise TemplateDoesNotExist(template_name, chain=chain)
django.template.exceptions.TemplateDoesNotExist: static/index.html
[2019-12-06 22:34:34,534] [ERROR] [log_message] : "GET /web_index/ HTTP/1.1" 500 83578
[2019-12-06 22:34:35,385] [WARNING] [get_response] : Not Found: /favicon.ico
[2019-12-06 22:34:35,386] [WARNING] [log_message] : "GET /favicon.ico HTTP/1.1" 404 11238
[2019-12-06 22:36:19,127] [ERROR] [handle_uncaught_exception] : Internal Server Error: /web_index/
Traceback (most recent call last):
  File "/Library/Frameworks/Python.framework/Versions/3.6/lib/python3.6/site-packages/django/core/handlers/exception.py", line 41, in inner
    response = get_response(request)
  File "/Library/Frameworks/Python.framework/Versions/3.6/lib/python3.6/site-packages/django/core/handlers/base.py", line 187, in _get_response
    response = self.process_exception_by_middleware(e, request)
  File "/Library/Frameworks/Python.framework/Versions/3.6/lib/python3.6/site-packages/django/core/handlers/base.py", line 185, in _get_response
    response = wrapped_callback(request, *callback_args, **callback_kwargs)
  File "/Library/Frameworks/Python.framework/Versions/3.6/lib/python3.6/site-packages/django/contrib/auth/decorators.py", line 23, in _wrapped_view
    return view_func(request, *args, **kwargs)
  File "/Users/zhuzhanhao/Testapi/Api/views.py", line 69, in web_index_views
    return render(request, 'static/index.html')
  File "/Library/Frameworks/Python.framework/Versions/3.6/lib/python3.6/site-packages/django/shortcuts.py", line 30, in render
    content = loader.render_to_string(template_name, context, request, using=using)
  File "/Library/Frameworks/Python.framework/Versions/3.6/lib/python3.6/site-packages/django/template/loader.py", line 67, in render_to_string
    template = get_template(template_name, using=using)
  File "/Library/Frameworks/Python.framework/Versions/3.6/lib/python3.6/site-packages/django/template/loader.py", line 25, in get_template
    raise TemplateDoesNotExist(template_name, chain=chain)
django.template.exceptions.TemplateDoesNotExist: static/index.html
[2019-12-06 22:36:19,198] [ERROR] [log_message] : "GET /web_index/ HTTP/1.1" 500 83578
[2019-12-06 22:36:22,257] [ERROR] [handle_uncaught_exception] : Internal Server Error: /web_index/
Traceback (most recent call last):
  File "/Library/Frameworks/Python.framework/Versions/3.6/lib/python3.6/site-packages/django/core/handlers/exception.py", line 41, in inner
    response = get_response(request)
  File "/Library/Frameworks/Python.framework/Versions/3.6/lib/python3.6/site-packages/django/core/handlers/base.py", line 187, in _get_response
    response = self.process_exception_by_middleware(e, request)
  File "/Library/Frameworks/Python.framework/Versions/3.6/lib/python3.6/site-packages/django/core/handlers/base.py", line 185, in _get_response
    response = wrapped_callback(request, *callback_args, **callback_kwargs)
  File "/Library/Frameworks/Python.framework/Versions/3.6/lib/python3.6/site-packages/django/contrib/auth/decorators.py", line 23, in _wrapped_view
    return view_func(request, *args, **kwargs)
  File "/Users/zhuzhanhao/Testapi/Api/views.py", line 69, in web_index_views
    return render(request, 'static/index.html')
  File "/Library/Frameworks/Python.framework/Versions/3.6/lib/python3.6/site-packages/django/shortcuts.py", line 30, in render
    content = loader.render_to_string(template_name, context, request, using=using)
  File "/Library/Frameworks/Python.framework/Versions/3.6/lib/python3.6/site-packages/django/template/loader.py", line 67, in render_to_string
    template = get_template(template_name, using=using)
  File "/Library/Frameworks/Python.framework/Versions/3.6/lib/python3.6/site-packages/django/template/loader.py", line 25, in get_template
    raise TemplateDoesNotExist(template_name, chain=chain)
django.template.exceptions.TemplateDoesNotExist: static/index.html
[2019-12-06 22:36:22,314] [ERROR] [log_message] : "GET /web_index/ HTTP/1.1" 500 83578
[2019-12-06 22:36:25,717] [ERROR] [handle_uncaught_exception] : Internal Server Error: /web_index/
Traceback (most recent call last):
  File "/Library/Frameworks/Python.framework/Versions/3.6/lib/python3.6/site-packages/django/core/handlers/exception.py", line 41, in inner
    response = get_response(request)
  File "/Library/Frameworks/Python.framework/Versions/3.6/lib/python3.6/site-packages/django/core/handlers/base.py", line 187, in _get_response
    response = self.process_exception_by_middleware(e, request)
  File "/Library/Frameworks/Python.framework/Versions/3.6/lib/python3.6/site-packages/django/core/handlers/base.py", line 185, in _get_response
    response = wrapped_callback(request, *callback_args, **callback_kwargs)
  File "/Library/Frameworks/Python.framework/Versions/3.6/lib/python3.6/site-packages/django/contrib/auth/decorators.py", line 23, in _wrapped_view
    return view_func(request, *args, **kwargs)
  File "/Users/zhuzhanhao/Testapi/Api/views.py", line 69, in web_index_views
    return render(request, 'static/index.html')
  File "/Library/Frameworks/Python.framework/Versions/3.6/lib/python3.6/site-packages/django/shortcuts.py", line 30, in render
    content = loader.render_to_string(template_name, context, request, using=using)
  File "/Library/Frameworks/Python.framework/Versions/3.6/lib/python3.6/site-packages/django/template/loader.py", line 67, in render_to_string
    template = get_template(template_name, using=using)
  File "/Library/Frameworks/Python.framework/Versions/3.6/lib/python3.6/site-packages/django/template/loader.py", line 25, in get_template
    raise TemplateDoesNotExist(template_name, chain=chain)
django.template.exceptions.TemplateDoesNotExist: static/index.html
[2019-12-06 22:36:25,780] [ERROR] [log_message] : "GET /web_index/ HTTP/1.1" 500 83578
[2019-12-06 22:41:15,253] [ERROR] [handle_uncaught_exception] : Internal Server Error: /web_index/
Traceback (most recent call last):
  File "/Library/Frameworks/Python.framework/Versions/3.6/lib/python3.6/site-packages/django/core/handlers/exception.py", line 41, in inner
    response = get_response(request)
  File "/Library/Frameworks/Python.framework/Versions/3.6/lib/python3.6/site-packages/django/core/handlers/base.py", line 187, in _get_response
    response = self.process_exception_by_middleware(e, request)
  File "/Library/Frameworks/Python.framework/Versions/3.6/lib/python3.6/site-packages/django/core/handlers/base.py", line 185, in _get_response
    response = wrapped_callback(request, *callback_args, **callback_kwargs)
  File "/Library/Frameworks/Python.framework/Versions/3.6/lib/python3.6/site-packages/django/contrib/auth/decorators.py", line 23, in _wrapped_view
    return view_func(request, *args, **kwargs)
  File "/Users/zhuzhanhao/Testapi/Api/views.py", line 69, in web_index_views
    return render(request, 'static/index.html')
  File "/Library/Frameworks/Python.framework/Versions/3.6/lib/python3.6/site-packages/django/shortcuts.py", line 30, in render
    content = loader.render_to_string(template_name, context, request, using=using)
  File "/Library/Frameworks/Python.framework/Versions/3.6/lib/python3.6/site-packages/django/template/loader.py", line 67, in render_to_string
    template = get_template(template_name, using=using)
  File "/Library/Frameworks/Python.framework/Versions/3.6/lib/python3.6/site-packages/django/template/loader.py", line 25, in get_template
    raise TemplateDoesNotExist(template_name, chain=chain)
django.template.exceptions.TemplateDoesNotExist: static/index.html
[2019-12-06 22:41:15,416] [ERROR] [log_message] : "GET /web_index/ HTTP/1.1" 500 83578
[2019-12-06 22:41:17,923] [ERROR] [handle_uncaught_exception] : Internal Server Error: /web_index/
Traceback (most recent call last):
  File "/Library/Frameworks/Python.framework/Versions/3.6/lib/python3.6/site-packages/django/core/handlers/exception.py", line 41, in inner
    response = get_response(request)
  File "/Library/Frameworks/Python.framework/Versions/3.6/lib/python3.6/site-packages/django/core/handlers/base.py", line 187, in _get_response
    response = self.process_exception_by_middleware(e, request)
  File "/Library/Frameworks/Python.framework/Versions/3.6/lib/python3.6/site-packages/django/core/handlers/base.py", line 185, in _get_response
    response = wrapped_callback(request, *callback_args, **callback_kwargs)
  File "/Library/Frameworks/Python.framework/Versions/3.6/lib/python3.6/site-packages/django/contrib/auth/decorators.py", line 23, in _wrapped_view
    return view_func(request, *args, **kwargs)
  File "/Users/zhuzhanhao/Testapi/Api/views.py", line 69, in web_index_views
    return render(request, 'static/index.html')
  File "/Library/Frameworks/Python.framework/Versions/3.6/lib/python3.6/site-packages/django/shortcuts.py", line 30, in render
    content = loader.render_to_string(template_name, context, request, using=using)
  File "/Library/Frameworks/Python.framework/Versions/3.6/lib/python3.6/site-packages/django/template/loader.py", line 67, in render_to_string
    template = get_template(template_name, using=using)
  File "/Library/Frameworks/Python.framework/Versions/3.6/lib/python3.6/site-packages/django/template/loader.py", line 25, in get_template
    raise TemplateDoesNotExist(template_name, chain=chain)
django.template.exceptions.TemplateDoesNotExist: static/index.html
[2019-12-06 22:41:17,978] [ERROR] [log_message] : "GET /web_index/ HTTP/1.1" 500 83578
[2019-12-06 22:50:46,861] [ERROR] [handle_uncaught_exception] : Internal Server Error: /web_index/
Traceback (most recent call last):
  File "/Library/Frameworks/Python.framework/Versions/3.6/lib/python3.6/site-packages/django/core/handlers/exception.py", line 41, in inner
    response = get_response(request)
  File "/Library/Frameworks/Python.framework/Versions/3.6/lib/python3.6/site-packages/django/core/handlers/base.py", line 187, in _get_response
    response = self.process_exception_by_middleware(e, request)
  File "/Library/Frameworks/Python.framework/Versions/3.6/lib/python3.6/site-packages/django/core/handlers/base.py", line 185, in _get_response
    response = wrapped_callback(request, *callback_args, **callback_kwargs)
  File "/Library/Frameworks/Python.framework/Versions/3.6/lib/python3.6/site-packages/django/contrib/auth/decorators.py", line 23, in _wrapped_view
    return view_func(request, *args, **kwargs)
  File "/Users/zhuzhanhao/Testapi/Api/views.py", line 69, in web_index_views
    return render(request, 'static/index.html')
  File "/Library/Frameworks/Python.framework/Versions/3.6/lib/python3.6/site-packages/django/shortcuts.py", line 30, in render
    content = loader.render_to_string(template_name, context, request, using=using)
  File "/Library/Frameworks/Python.framework/Versions/3.6/lib/python3.6/site-packages/django/template/loader.py", line 67, in render_to_string
    template = get_template(template_name, using=using)
  File "/Library/Frameworks/Python.framework/Versions/3.6/lib/python3.6/site-packages/django/template/loader.py", line 25, in get_template
    raise TemplateDoesNotExist(template_name, chain=chain)
django.template.exceptions.TemplateDoesNotExist: static/index.html
[2019-12-06 22:50:46,934] [ERROR] [log_message] : "GET /web_index/ HTTP/1.1" 500 83578
[2019-12-06 22:50:48,631] [ERROR] [handle_uncaught_exception] : Internal Server Error: /web_index/
Traceback (most recent call last):
  File "/Library/Frameworks/Python.framework/Versions/3.6/lib/python3.6/site-packages/django/core/handlers/exception.py", line 41, in inner
    response = get_response(request)
  File "/Library/Frameworks/Python.framework/Versions/3.6/lib/python3.6/site-packages/django/core/handlers/base.py", line 187, in _get_response
    response = self.process_exception_by_middleware(e, request)
  File "/Library/Frameworks/Python.framework/Versions/3.6/lib/python3.6/site-packages/django/core/handlers/base.py", line 185, in _get_response
    response = wrapped_callback(request, *callback_args, **callback_kwargs)
  File "/Library/Frameworks/Python.framework/Versions/3.6/lib/python3.6/site-packages/django/contrib/auth/decorators.py", line 23, in _wrapped_view
    return view_func(request, *args, **kwargs)
  File "/Users/zhuzhanhao/Testapi/Api/views.py", line 69, in web_index_views
    return render(request, 'static/index.html')
  File "/Library/Frameworks/Python.framework/Versions/3.6/lib/python3.6/site-packages/django/shortcuts.py", line 30, in render
    content = loader.render_to_string(template_name, context, request, using=using)
  File "/Library/Frameworks/Python.framework/Versions/3.6/lib/python3.6/site-packages/django/template/loader.py", line 67, in render_to_string
    template = get_template(template_name, using=using)
  File "/Library/Frameworks/Python.framework/Versions/3.6/lib/python3.6/site-packages/django/template/loader.py", line 25, in get_template
    raise TemplateDoesNotExist(template_name, chain=chain)
django.template.exceptions.TemplateDoesNotExist: static/index.html
[2019-12-06 22:50:48,692] [ERROR] [log_message] : "GET /web_index/ HTTP/1.1" 500 83578
[2019-12-06 22:50:59,610] [ERROR] [handle_uncaught_exception] : Internal Server Error: /web_index/
Traceback (most recent call last):
  File "/Library/Frameworks/Python.framework/Versions/3.6/lib/python3.6/site-packages/django/core/handlers/exception.py", line 41, in inner
    response = get_response(request)
  File "/Library/Frameworks/Python.framework/Versions/3.6/lib/python3.6/site-packages/django/core/handlers/base.py", line 187, in _get_response
    response = self.process_exception_by_middleware(e, request)
  File "/Library/Frameworks/Python.framework/Versions/3.6/lib/python3.6/site-packages/django/core/handlers/base.py", line 185, in _get_response
    response = wrapped_callback(request, *callback_args, **callback_kwargs)
  File "/Library/Frameworks/Python.framework/Versions/3.6/lib/python3.6/site-packages/django/contrib/auth/decorators.py", line 23, in _wrapped_view
    return view_func(request, *args, **kwargs)
  File "/Users/zhuzhanhao/Testapi/Api/views.py", line 69, in web_index_views
    return render(request, 'static/index.html')
  File "/Library/Frameworks/Python.framework/Versions/3.6/lib/python3.6/site-packages/django/shortcuts.py", line 30, in render
    content = loader.render_to_string(template_name, context, request, using=using)
  File "/Library/Frameworks/Python.framework/Versions/3.6/lib/python3.6/site-packages/django/template/loader.py", line 67, in render_to_string
    template = get_template(template_name, using=using)
  File "/Library/Frameworks/Python.framework/Versions/3.6/lib/python3.6/site-packages/django/template/loader.py", line 25, in get_template
    raise TemplateDoesNotExist(template_name, chain=chain)
django.template.exceptions.TemplateDoesNotExist: static/index.html
[2019-12-06 22:50:59,686] [ERROR] [log_message] : "GET /web_index/ HTTP/1.1" 500 83593
[2019-12-06 22:53:04,992] [WARNING] [get_response] : Not Found: /web_index/.static.images.json
[2019-12-06 22:53:04,994] [WARNING] [log_message] : "GET /web_index/.static.images.json HTTP/1.1" 404 11292
[2019-12-06 22:53:09,433] [WARNING] [get_response] : Not Found: /web_index/.static.images.json
[2019-12-06 22:53:09,433] [WARNING] [log_message] : "GET /web_index/.static.images.json HTTP/1.1" 404 11292
[2019-12-06 22:53:11,448] [WARNING] [get_response] : Not Found: /web_index/.static.images.json
[2019-12-06 22:53:11,449] [WARNING] [log_message] : "GET /web_index/.static.images.json HTTP/1.1" 404 11292
[2019-12-06 22:53:48,837] [WARNING] [get_response] : Not Found: /web_index/.static.images.json
[2019-12-06 22:53:48,838] [WARNING] [log_message] : "GET /web_index/.static.images.json HTTP/1.1" 404 11292
[2019-12-06 22:57:16,040] [WARNING] [get_response] : Not Found: /web_index/.static.images.json
[2019-12-06 22:57:16,044] [WARNING] [log_message] : "GET /web_index/.static.images.json HTTP/1.1" 404 11292
[2019-12-06 22:57:16,583] [WARNING] [get_response] : Not Found: /web_index/.static.images.json
[2019-12-06 22:57:16,583] [WARNING] [log_message] : "GET /web_index/.static.images.json HTTP/1.1" 404 11292
[2019-12-06 23:01:05,799] [WARNING] [get_response] : Not Found: /Web/static/layui/css/layui.css
[2019-12-06 23:01:05,818] [WARNING] [log_message] : "GET /Web/static/layui/css/layui.css HTTP/1.1" 404 11295
[2019-12-06 23:01:05,817] [WARNING] [get_response] : Not Found: /Web/static/layui/layui.js
[2019-12-06 23:01:05,821] [WARNING] [log_message] : "GET /Web/static/layui/layui.js HTTP/1.1" 404 11280
[2019-12-06 23:01:13,746] [WARNING] [get_response] : Not Found: /Web/static/layui/css/layui.css
[2019-12-06 23:01:13,753] [WARNING] [log_message] : "GET /Web/static/layui/css/layui.css HTTP/1.1" 404 11295
[2019-12-06 23:01:13,765] [WARNING] [get_response] : Not Found: /Web/static/layui/layui.js
[2019-12-06 23:01:13,765] [WARNING] [log_message] : "GET /Web/static/layui/layui.js HTTP/1.1" 404 11280
[2019-12-06 23:02:17,231] [WARNING] [get_response] : Not Found: /Web/static/layui/css/layui.css
[2019-12-06 23:02:17,243] [WARNING] [get_response] : Not Found: /Web/static/layui/layui.js
[2019-12-06 23:02:17,244] [WARNING] [log_message] : "GET /Web/static/layui/css/layui.css HTTP/1.1" 404 11295
[2019-12-06 23:02:17,245] [WARNING] [log_message] : "GET /Web/static/layui/layui.js HTTP/1.1" 404 11280
[2019-12-06 23:04:22,333] [WARNING] [get_response] : Not Found: /Web/static/layui/css/layui.css
[2019-12-06 23:04:22,334] [WARNING] [get_response] : Not Found: /Web/static/layui/layui.js
[2019-12-06 23:04:22,335] [WARNING] [log_message] : "GET /Web/static/layui/layui.js HTTP/1.1" 404 11280
[2019-12-06 23:04:22,348] [WARNING] [log_message] : "GET /Web/static/layui/css/layui.css HTTP/1.1" 404 11295
[2019-12-06 23:04:25,829] [WARNING] [get_response] : Not Found: /Web/static/layui/css/layui.css
[2019-12-06 23:04:25,832] [WARNING] [log_message] : "GET /Web/static/layui/css/layui.css HTTP/1.1" 404 11295
[2019-12-06 23:04:25,853] [WARNING] [get_response] : Not Found: /Web/static/layui/layui.js
[2019-12-06 23:04:25,854] [WARNING] [log_message] : "GET /Web/static/layui/layui.js HTTP/1.1" 404 11280
[2019-12-06 23:04:28,791] [WARNING] [get_response] : Not Found: /web_linklist/.static.images.json
[2019-12-06 23:04:28,792] [WARNING] [log_message] : "GET /web_linklist/.static.images.json?page=1&limit=20 HTTP/1.1" 404 11321
[2019-12-06 23:05:13,426] [WARNING] [get_response] : Not Found: /Web/static/layui/css/layui.css
[2019-12-06 23:05:13,442] [WARNING] [get_response] : Not Found: /Web/static/layui/layui.js
[2019-12-06 23:05:13,443] [WARNING] [log_message] : "GET /Web/static/layui/css/layui.css HTTP/1.1" 404 11295
[2019-12-06 23:05:13,443] [WARNING] [log_message] : "GET /Web/static/layui/layui.js HTTP/1.1" 404 11280
[2019-12-06 23:23:04,419] [WARNING] [log_message] : "GET /static/images/login_bg.jpg HTTP/1.1" 404 1670
[2019-12-06 23:34:43,585] [WARNING] [get_response] : Not Found: /favicon.ico
[2019-12-06 23:34:43,588] [WARNING] [log_message] : "GET /favicon.ico HTTP/1.1" 404 11238
[2019-12-07 00:15:21,963] [WARNING] [get_response] : Not Found: /web_info/.static.images.json
[2019-12-07 00:15:21,967] [WARNING] [log_message] : "GET /web_info/.static.images.json HTTP/1.1" 404 11289
[2019-12-07 00:27:28,719] [ERROR] [handle_uncaught_exception] : Internal Server Error: /apilist/
Traceback (most recent call last):
  File "/Library/Frameworks/Python.framework/Versions/3.6/lib/python3.6/site-packages/django/core/handlers/exception.py", line 41, in inner
    response = get_response(request)
  File "/Library/Frameworks/Python.framework/Versions/3.6/lib/python3.6/site-packages/django/core/handlers/base.py", line 187, in _get_response
    response = self.process_exception_by_middleware(e, request)
  File "/Library/Frameworks/Python.framework/Versions/3.6/lib/python3.6/site-packages/django/core/handlers/base.py", line 185, in _get_response
    response = wrapped_callback(request, *callback_args, **callback_kwargs)
  File "/Users/zhuzhanhao/Testapi/Api/api/view_api.py", line 145, in apilist_view
    apilists = Case.objects.filter(Q(belong__contains="库房接口") & Q(system="tdr")).order_by("sortid")
NameError: name 'Case' is not defined
[2019-12-07 00:27:29,628] [ERROR] [log_message] : "GET /apilist/?page=1&limit=30&belong=warehouse&system=tdr HTTP/1.1" 500 14876
[2019-12-07 14:01:33,225] [WARNING] [log_message] : "GET /static/images/login_bg.jpg HTTP/1.1" 404 1670
